Workbook
Name A: #REF!
Name AA: #REF!
Name ACABADO: #REF!
Name ALUMINA: #REF!
Name ALUMINIO: #REF!
Name CLASSIC: #REF!
Name COLOR: #REF!
Name CRISTAL: #REF!
Name ESPESOR: #REF!
Name LINEA: #REF!
Name PREMIUM: #REF!
Name PRIMAVERA: #REF!
Name REFUERZO: #REF!
Name SG3_: #REF!
Name SG40_: #REF!
Name SG40_PB: #REF!
Name SG5_: #REF!
Name TRADICIONAL: #REF!
Name VANO: #REF!
Name VENECIA: #REF!

Sheet BD GN
B1: SISTEMAS | C1: SISTEMAS | E1: CERRADURAS | G1: CRISTALES | I1: ACABADO ALUMINIO | K1: LINEA CLIENTE | M1: FORMA DE PAGO | O1: PROTECCIÓN | Q1: SANDBLASTING | T1: VIS | V1: ALFAJÍA | X1: ELABORADO | Z1: OBSERVACIONES | AB1: SANDBLASTING | AD1: CIUDADES | AF1: UNIDAD DE NEGOCIO | AH1: EMBALAJE | AP1: SILICONA | AW1: PELICULA PROTECCION | BD1: TRANSPORTE | BO1: BACKOFFICE OPERATIVO | BT1: VIATICOS | BY1: VIATICOS INTERMUNICIPALES | CB1: SISTEMAS | CC1: BGA | CD1: BTA | CE1: ANTQ | CF1: VALLE | CG1: COSTA | CI1: 0.1 | CK1: BGA | CL1: BTA | CM1: ANTQ | CN1: VALLE | CO1: COSTA | CQ1: SISTEMAS | CR1: LINEA | CS1: M2 | CT1: VR TOTAL | CU1: VR M2 | CX1: LINEA | CY1: M2 | CZ1: VR TOTAL | DA1: VR M2 | DF1: RAD | DG1: CANTIDAD | DH1: SUBTOTAL | DI1: TOTAL | DJ1: ALU | DK1: ACC | DL1: VIDRIO | DM1: TRANSPORTE | DN1: VIATICOS | DO1: BACKOFFICE | DP1: GAST VENTA | DQ1: GAST FINANC | DR1: COSTOS IND | DS1: ENSAMBLE | DT1: INSTALACION | DU1: M2 INOX | DV1: M2 ALU | DW1: VR INOX | DX1: VR ALU
B2: VENTANA CORREDIZA LINEA PREMIUM TIPO EUROPEO SISTEMA VENECIA SERIE 50 | C2: VENTANA CORREDIZA LINEA PREMIUM TIPO EUROPEO VENECIA MONZA | E2: CIERRE EMBUTIDO DE IMPACTO AUTOMATICO | G2: COMPOSICION LAMINADO CRUDO 4 MM INC + PVB 0,38 MM INC + 4 MM INC | I2: ALUCOLOR POLIESTER NEGRO MATE PP13 | K2: PROFESIONALES | M2: CREDITO | O2: UNA CARA | Q2: SI | T2: SI | V2: SI | X2: IVAN CANDELA | Z2: INCLUYE ENGANCHES TOTALMENTE REFORZADOS | AB2: 50000 | AD2: BGA | AF2: SILVER | AH2: CARTON | AJ2: PROVEEDOR | AK2: PELEX | AM2: PROVEEDOR | AN2: VR ML | AP2: FACTOR CONVERSION | AQ2: ML TUBO | AR2: VR TUBO SILICONA | AS2: VR SILICONA ML | AT2: PROVEEDOR | AU2: VR ML X VEN | AW2: ANCHO M | AX2: ALTO M | AY2: AREA M2 | AZ2: VR ROLLO | BA2: PROVEEDOR | BB2: VR M2 | BD2: CIUDAD | BE2: VR VIAJE | BF2: P/CUESTA | BG2: RUITOQUE | BH2: RUITOQ BAJO | BI2: F/BLANCA | BJ2: CAPACIDAD CARGA KG | BK2: % DE CARGA | BL2: PROVEEDOR | BM2: VR KG | BO2: PARTICIPA | BP2: VR SALARIO | BQ2: VR PRESTACIONES | BR2: VR DIA | BT2: CIUDAD | BU2: VR DIA ALIMENTACION | BV2: VR HAB | BW2: VR DIA | BY2: CIUDAD | BZ2: VR IDA Y VUELTA | CB2: =C2 -> VENTANA CORREDIZA LINEA PREMIUM TIPO EUROPEO VENECIA MONZA | CC2: 622000 | CD2: 715000 | CE2: 872000 | CJ2: M2 REFERENCIA | CK2: =(565000*CI1)+565000 -> 621500 | CL2: =656700+(656700*CI1) -> 722370 | CM2: =802000+(802000*CI1) -> 882200 | CQ2: =C2 -> VENTANA CORREDIZA LINEA PREMIUM TIPO EUROPEO VENECIA MONZA | CR2: LA | CS2: =SUMIF(COTIZACIÓN!$D$15:$L$335,'BD GN'!CQ2,COTIZACIÓN!$L$15:$L$335) -> 0 | CT2: =SUMIF(COTIZACIÓN!$D$15:$O$335,'BD GN'!CQ2,COTIZACIÓN!$O$15:$O$335) -> 0 | CU2: =IFERROR(CT2/CS2,"0") -> 0 | CW2: =IFERROR(CZ2/CZ4,"0%") -> 0% | CX2: LA | CY2: =SUMIF($CR:$CU,CX2,$CS:$CS) -> 0 | CZ2: =SUMIF($CR:$CU,CX2,$CT:$CT) -> 0 | DA2: =IFERROR(CZ2/CY2,"0") -> 0 | DG2: =SUMIF(COTIZACIÓN!DG:DH,'BD GN'!$DF$2,COTIZACIÓN!DH:DH) -> 0 | DH2: =SUMIF(COTIZACIÓN!DG:DI,'BD GN'!$DF$2,COTIZACIÓN!DI:DI) -> 0 | DI2: =SUMIF(COTIZACIÓN!DG:DJ,'BD GN'!$DF$2,COTIZACIÓN!DJ:DJ) -> 0 | DJ2: =SUMIF(COTIZACIÓN!DG:DK,'BD GN'!$DF$2,COTIZACIÓN!DK:DK) -> #VALUE! | DK2: =SUMIF(COTIZACIÓN!DG:DL,'BD GN'!$DF$2,COTIZACIÓN!DL:DL) -> 0.07483939 | DL2: =SUMIF(COTIZACIÓN!DG:DM,'BD GN'!$DF$2,COTIZACIÓN!DM:DM) -> 0.06753794 | DM2: =SUMIF(COTIZACIÓN!DG:DN,'BD GN'!$DF$2,COTIZACIÓN!DN:DN) -> 0.063799022 | DN2: =SUMIF(COTIZACIÓN!DG:DO,'BD GN'!$DF$2,COTIZACIÓN!DO:DO) -> #VALUE! | DO2: =SUMIF(COTIZACIÓN!DG:DP,'BD GN'!$DF$2,COTIZACIÓN!DP:DP) -> #VALUE! | DP2: =SUMIF(COTIZACIÓN!DG:DQ,'BD GN'!$DF$2,COTIZACIÓN!DQ:DQ) -> #VALUE! | DQ2: =SUMIF(COTIZACIÓN!DG:DR,'BD GN'!$DF$2,COTIZACIÓN!DR:DR) -> 0 | DR2: =SUMIF(COTIZACIÓN!DG:DS,'BD GN'!$DF$2,COTIZACIÓN!DS:DS) -> 0 | DS2: =SUMIF(COTIZACIÓN!DG:DT,'BD GN'!$DF$2,COTIZACIÓN!DT:DT) -> 0 | DT2: =SUMIF(COTIZACIÓN!DG:DU,'BD GN'!$DF$2,COTIZACIÓN!DU:DU) -> 0 | DU2: =SUMIF(COTIZACIÓN!DG:DV,'BD GN'!$DF$2,COTIZACIÓN!DV:DV) -> 0 | DV2: =SUMIF(COTIZACIÓN!DG:DW,'BD GN'!$DF$2,COTIZACIÓN!DW:DW) -> 0 | DW2: =SUMIF(COTIZACIÓN!DG:DX,'BD GN'!$DF$2,COTIZACIÓN!DX:DX) -> 0 | DX2: =SUMIF(COTIZACIÓN!DG:DY,'BD GN'!$DF$2,COTIZACIÓN!DY:DY) -> 0
B3: PUERTA CORREDIZA LINEA PREMIUM TIPO EUROPEO SISTEMA VENECIA SERIE 70 | C3: PUERTA CORREDIZA LINEA PREMIUM TIPO EUROPEO VENECIA NAPOLES | E3: CERRADURA MULTI-PUNTO MANIJA ITALIANA | G3: COMPOSICION LAMINADO CRUDO 5 MM INC + PVB 0,38 MM INC + 5 MM INC | I3: ALUCOLOR POLIESTER PINTURA GRIS | K3: CLIENTE FINAL | M3: ACORDADA | O3: DOS CARAS | Q3: NO | T3: NO | V3: NO | X3: LUISA HERNÁNDEZ | Z3: INCLUYE ENGANCHES SENCILLOS | AD3: BTA | AF3: BRONZE | AH3: VR TIRA | AI3: VR ML | AK3: VR ROLLO | AL3: VR ML | AN3: TOTAL | AP3: 0.09 | AQ3: 305 | AR3: 24000 | AS3: =AP3*AR3 -> 2160 | AU3: =AS3 -> 2160 | AW3: 1.22 | AX3: 500 | AY3: =AW3*AX3 -> 610 | AZ3: =775000*1.19 -> 922250 | BB3: =AZ3/AY3 -> 1511.8852 | BD3: BGA | BE3: 300000 | BF3: 170000 | BG3: 190000 | BH3: 170000 | BI3: 140000 | BJ3: 2500 | BK3: 0.8 | BM3: =IFERROR(BE3/(BJ3*BK3),"0") -> 150 | BO3: SISO | BP3: 1500000 | BQ3: =BP3*40% -> 600000 | BR3: =(BP3+BQ3)/30 -> 70000 | BT3: BGA | BU3: 0 | BV3: 0 | BW3: =BU3+BV3 -> 0 | BY3: BGA | BZ3: 10000 | CB3: =C3 -> PUERTA CORREDIZA LINEA PREMIUM TIPO EUROPEO VENECIA NAPOLES | CC3: 576000 | CD3: 539000 | CE3: 777000 | CQ3: =C3 -> PUERTA CORREDIZA LINEA PREMIUM TIPO EUROPEO VENECIA NAPOLES | CR3: LA | CS3: =SUMIF(COTIZACIÓN!$D$15:$L$335,'BD GN'!CQ3,COTIZACIÓN!$L$15:$L$335) -> 0 | CT3: =SUMIF(COTIZACIÓN!$D$15:$O$335,'BD GN'!CQ3,COTIZACIÓN!$O$15:$O$335) -> 0 | CU3: =IFERROR(CT3/CS3,"0") -> 0 | CW3: =IFERROR(CZ3/CZ4,"0%") -> 0% | CX3: LI | CY3: =SUMIF($CR:$CU,CX3,$CS:$CS) -> 0 | CZ3: =SUMIF($CR:$CU,CX3,$CT:$CT) -> 0 | DA3: =IFERROR(CZ3/CY3,"0") -> 0
B4: PUERTA CORREDIZA LINEA PREMIUM TIPO EUROPEO SISTEMA VENECIA SERIE 100 | C4: PUERTA CORREDIZA LINEA PREMIUM TIPO EUROPEO VENECIA MONACO | E4: CERRADURA MULTI-PUNTO MANIJA ITALIANA | G4: COMPOSICION LAMINADO CRUDO 4 MM INC + PVB 0,38 MM GRIS + 4 MM INC | I4: ALUCOLOR POLIESTER BLANCO PP003 | Z4: INCLUYE ENGANCHES MIXTOS | AD4: ANTQ | AF4: GOLD | AH4: =170000/800 -> 212.5 | AI4: =AH4/1.35 -> 157.40741 | AK4: 6800 | AL4: =AK4/305 -> 22.295082 | AN4: =AI4+AL4 -> 179.70249 | BD4: BTA | BE4: 1500000 | BJ4: 6000 | BK4: 0.7 | BM4: =IFERROR(BE4/(BJ4*BK4),"0") -> 357.14286 | BO4: MONTAJE | BP4: 1500000 | BQ4: =BP4*40% -> 600000 | BR4: =(BP4+BQ4)/30 -> 70000 | BT4: BTA | BU4: 45000 | BV4: 65000 | BW4: =BU4+BV4 -> 110000 | BY4: BTA | BZ4: 280000 | CB4: =C4 -> PUERTA CORREDIZA LINEA PREMIUM TIPO EUROPEO VENECIA MONACO | CC4: 863000 | CE4: 1063220 | CQ4: =C4 -> PUERTA CORREDIZA LINEA PREMIUM TIPO EUROPEO VENECIA MONACO | CR4: LA | CS4: =SUMIF(COTIZACIÓN!$D$15:$L$335,'BD GN'!CQ4,COTIZACIÓN!$L$15:$L$335) -> 0 | CT4: =SUMIF(COTIZACIÓN!$D$15:$O$335,'BD GN'!CQ4,COTIZACIÓN!$O$15:$O$335) -> 0 | CU4: =IFERROR(CT4/CS4,"0") -> 0 | CX4: GLB | CY4: =CY2+CY3 -> 0 | CZ4: =CZ2+CZ3 -> 0 | DA4: =IFERROR(CZ4/CY4,"0") -> 0
B5: CUERPO FIJO LINEA PREMIUM TIPO EUROPEO SISTEMA VENECIA SERIE 40 | C5: CUERPO FIJO LINEA PREMIUM TIPO EUROPEO VENECIA FERMO | E5: N.A | G5: COMPOSICION LAMINADO CRUDO 5 MM INC + PVB 0,38 MM GRIS + 5 MM INC | I5: ALUCOLOR POLIESTER PINTURA CHAMPAÑA | Q5: RENDIMIENTO SIKA FORCE | R5: 1.5 | S5: gr/cm3 | X5: VERSIÓN | Z5: NO INCLUYE ALFAJIA | AD5: VALLE | AF5: PLATINUM | BD5: ANTQ | BE5: 1800000 | BJ5: 6000 | BK5: 0.7 | BM5: =IFERROR(BE5/(BJ5*BK5),"0") -> 428.57143 | BT5: ANTQ | BU5: 45000 | BV5: 65000 | BW5: =BU5+BV5 -> 110000 | BY5: ANTQ | BZ5: 280000 | CB5: =C5 -> CUERPO FIJO LINEA PREMIUM TIPO EUROPEO VENECIA FERMO | CC5: 470000 | CD5: 407000 | CE5: 783000 | CQ5: =C5 -> CUERPO FIJO LINEA PREMIUM TIPO EUROPEO VENECIA FERMO | CR5: LA | CS5: =SUMIF(COTIZACIÓN!$D$15:$L$335,'BD GN'!CQ5,COTIZACIÓN!$L$15:$L$335) -> 0 | CT5: =SUMIF(COTIZACIÓN!$D$15:$O$335,'BD GN'!CQ5,COTIZACIÓN!$O$15:$O$335) -> 0 | CU5: =IFERROR(CT5/CS5,"0") -> 0
B6: CUERPO PROYECTANTE LINEA PREMIUM TIPO EUROPEO SISTEMA VENECIA SERIE 40 | C6: CUERPO PROYECTANTE LINEA PREMIUM TIPO EUROPEO VENECIA FERMO | E6: MANIJA CREMONA ITALIANA | G6: COMPOSICION CONTROL SOLAR QUALITY GLASS PREMIUM LAMINADO CRUDO 4 MM INC + PVB 0,38 MM INC + 4 MM CL167 | I6: ANODIZADO BLANCO MATE AN001 | Q6: CUÑETE | R6: 30000 | S6: gr | T6: =(641960+173460)*1.19 -> 970349.8 | X6: SG CLASSIC | Z6: MARCO EN SG47 | AD6: COSTA | AF6: CUSTOM | BD6: CALI | BE6: 2200000 | BJ6: 6000 | BK6: 0.7 | BM6: =IFERROR(BE6/(BJ6*BK6),"0") -> 523.80952 | BT6: CALI | BU6: 45000 | BV6: 65000 | BW6: =BU6+BV6 -> 110000 | BY6: CALI | BZ6: 320000 | CB6: =C6 -> CUERPO PROYECTANTE LINEA PREMIUM TIPO EUROPEO VENECIA FERMO | CC6: 470000 | CD6: 407000 | CE6: 783000 | CQ6: =C6 -> CUERPO PROYECTANTE LINEA PREMIUM TIPO EUROPEO VENECIA FERMO | CR6: LA | CS6: =SUMIF(COTIZACIÓN!$D$15:$L$335,'BD GN'!CQ6,COTIZACIÓN!$L$15:$L$335) -> 0 | CT6: =SUMIF(COTIZACIÓN!$D$15:$O$335,'BD GN'!CQ6,COTIZACIÓN!$O$15:$O$335) -> 0 | CU6: =IFERROR(CT6/CS6,"0") -> 0
B7: PUERTA BATIENTE LINEA PREMIUM TIPO EUROPEO SISTEMA VENECIA SERIE 40 | C7: PUERTA BATIENTE LINEA PREMIUM TIPO EUROPEO VENECIA FERMO | E7: MANIJA DOBLE CONFORT | G7: COMPOSICION CONTROL SOLAR QUALITY GLASS PREMIUM LAMINADO CRUDO 4 MM INC + PVB 0,38 MM INC + 4 MM CL120 | I7: N.A | Q7: medidas del perfil F Para 1m | R7: =10*1.3*100 -> 1300 | S7: cm3 | X7: SG ESENCIAL | Z7: MARCO EN SG58 | AF7: CONFORT | BD7: COSTA | BE7: 1800000 | BJ7: 6000 | BK7: 0.7 | BM7: =IFERROR(BE7/(BJ7*BK7),"0") -> 428.57143 | BT7: COSTA | BU7: 45000 | BV7: 65000 | BW7: =BU7+BV7 -> 110000 | BY7: COSTA | BZ7: 350000 | CB7: =C7 -> PUERTA BATIENTE LINEA PREMIUM TIPO EUROPEO VENECIA FERMO | CQ7: =C7 -> PUERTA BATIENTE LINEA PREMIUM TIPO EUROPEO VENECIA FERMO | CR7: LA | CS7: =SUMIF(COTIZACIÓN!$D$15:$L$335,'BD GN'!CQ7,COTIZACIÓN!$L$15:$L$335) -> 0 | CT7: =SUMIF(COTIZACIÓN!$D$15:$O$335,'BD GN'!CQ7,COTIZACIÓN!$O$15:$O$335) -> 0 | CU7: =IFERROR(CT7/CS7,"0") -> 0
B8: VENTANA CORREDIZA LINEA CLASSIC SISTEMA PRIMAVERA SERIE SG 3 | C8: VENTANA CORREDIZA LINEA CLASSIC SISTEMA PRIMAVERA SERIE SG 3 | E8: CIERRE EMBUTIDO DE IMPACTO AUTOMATICO | G8: COMPOSICION CONTROL SOLAR QUALITY GLASS PREMIUM LAMINADO CRUDO 4 MM INC + PVB 0,38 MM INC + 4 MM CL150 | Q8: valor por mL de pasamanos | R8: =+R7*R5 -> 1950 | S8: gr | T8: =+(R8*T6)/R6 -> 63072.737 | X8: SG BIOCONFORT | Z8: VERTICOS 636 Y 688 | BD8: CUCUTA | BE8: 1200000 | BJ8: 8000 | BK8: 0.7 | BM8: =IFERROR(BE8/(BJ8*BK8),"0") -> 214.28571 | CB8: =C8 -> VENTANA CORREDIZA LINEA CLASSIC SISTEMA PRIMAVERA SERIE SG 3 | CQ8: =C8 -> VENTANA CORREDIZA LINEA CLASSIC SISTEMA PRIMAVERA SERIE SG 3 | CR8: LA | CS8: =SUMIF(COTIZACIÓN!$D$15:$L$335,'BD GN'!CQ8,COTIZACIÓN!$L$15:$L$335) -> 0 | CT8: =SUMIF(COTIZACIÓN!$D$15:$O$335,'BD GN'!CQ8,COTIZACIÓN!$O$15:$O$335) -> 0 | CU8: =IFERROR(CT8/CS8,"0") -> 0
B9: VENTANA CORREDIZA LINEA CLASSIC SISTEMA PRIMAVERA SERIE SG 5 | C9: VENTANA CORREDIZA LINEA CLASSIC PRIMAVERA LAGO | E9: CIERRE EMBUTIDO DE IMPACTO AUTOMATICO | G9: COMPOSICION CONTROL SOLAR QUALITY GLASS CLASSIC LAMINADO CRUDO 4 MM INC + PVB 0,38 MM INC + 4 MM GREEN | X9: SG SIGNATURE | Z9: VERTICOS 688 Y 1860 | CB9: =C9 -> VENTANA CORREDIZA LINEA CLASSIC PRIMAVERA LAGO | CC9: 442000 | CE9: 649000 | CQ9: =C9 -> VENTANA CORREDIZA LINEA CLASSIC PRIMAVERA LAGO | CR9: LA | CS9: =SUMIF(COTIZACIÓN!$D$15:$L$335,'BD GN'!CQ9,COTIZACIÓN!$L$15:$L$335) -> 0 | CT9: =SUMIF(COTIZACIÓN!$D$15:$O$335,'BD GN'!CQ9,COTIZACIÓN!$O$15:$O$335) -> 0 | CU9: =IFERROR(CT9/CS9,"0") -> 0
B10: PUERTA CORREDIZA LINEA CLASSIC SISTEMA PRIMAVERA SERIE SG 5 | C10: PUERTA CORREDIZA LINEA CLASSIC PRIMAVERA LAGO | E10: CIERRE EMBUTIDO DE IMPACTO | G10: COMPOSICION CONTROL SOLAR QUALITY GLASS CLASSIC LAMINADO CRUDO 4 MM INC + PVB 0,38 MM INC + 4 MM BLUE | Z10: SISTEMA DESLIZANTE | CB10: =C10 -> PUERTA CORREDIZA LINEA CLASSIC PRIMAVERA LAGO | CC10: 442000 | CQ10: =C10 -> PUERTA CORREDIZA LINEA CLASSIC PRIMAVERA LAGO | CR10: LA | CS10: =SUMIF(COTIZACIÓN!$D$15:$L$335,'BD GN'!CQ10,COTIZACIÓN!$L$15:$L$335) -> 0 | CT10: =SUMIF(COTIZACIÓN!$D$15:$O$335,'BD GN'!CQ10,COTIZACIÓN!$O$15:$O$335) -> 0 | CU10: =IFERROR(CT10/CS10,"0") -> 0
B11: VENTANA CORREDIZA LINEA CLASSIC SISTEMA PRIMAVERA SERIE SG 8 | C11: VENTANA CORREDIZA LINEA CLASSIC PRIMAVERA LUCCA | E11: CIERRE EMBUTIDO DE IMPACTO AUTOMATICO | G11: COMPOSICION CONTROL SOLAR QUALITY GLASS CLASSIC LAMINADO CRUDO 4 MM INC + PVB 0,38 MM INC + 4 MM BRONZE | Z11: SISTEMA BATIENTE | CB11: =C11 -> VENTANA CORREDIZA LINEA CLASSIC PRIMAVERA LUCCA | CC11: 411000 | CQ11: =C11 -> VENTANA CORREDIZA LINEA CLASSIC PRIMAVERA LUCCA | CR11: LA | CS11: =SUMIF(COTIZACIÓN!$D$15:$L$335,'BD GN'!CQ11,COTIZACIÓN!$L$15:$L$335) -> 0 | CT11: =SUMIF(COTIZACIÓN!$D$15:$O$335,'BD GN'!CQ11,COTIZACIÓN!$O$15:$O$335) -> 0 | CU11: =IFERROR(CT11/CS11,"0") -> 0
B12: PUERTA CORREDIZA LINEA CLASSIC SISTEMA PRIMAVERA SERIE SG 8 | C12: PUERTA CORREDIZA LINEA CLASSIC PRIMAVERA LUCCA | E12: CIERRE EMBUTIDO DE IMPACTO | G12: COMPOSICION MONOLITICO TEMPLADO 10 MM INC | CB12: =C12 -> PUERTA CORREDIZA LINEA CLASSIC PRIMAVERA LUCCA | CC12: 411000 | CQ12: =C12 -> PUERTA CORREDIZA LINEA CLASSIC PRIMAVERA LUCCA | CR12: LA | CS12: =SUMIF(COTIZACIÓN!$D$15:$L$335,'BD GN'!CQ12,COTIZACIÓN!$L$15:$L$335) -> 0 | CT12: =SUMIF(COTIZACIÓN!$D$15:$O$335,'BD GN'!CQ12,COTIZACIÓN!$O$15:$O$335) -> 0 | CU12: =IFERROR(CT12/CS12,"0") -> 0
B13: CUERPO BATIENTE LINEA PREMIUM TIPO EUROPEO SISTEMA VENECIA SERIE 40 | C13: CUERPO BATIENTE LINEA PREMIUM TIPO EUROPEO VENECIA FERMO | E13: MANIJA CREMONA ITALIANA | G13: COMPOSICION MONOLITICO TEMPLADO 8 MM INC | Z13: INCLUYE TUBULAR SGT-101-103-117 | CB13: =C13 -> CUERPO BATIENTE LINEA PREMIUM TIPO EUROPEO VENECIA FERMO | CC13: 470000 | CD13: 407000 | CE13: 738000 | CQ13: =C13 -> CUERPO BATIENTE LINEA PREMIUM TIPO EUROPEO VENECIA FERMO | CR13: LA | CS13: =SUMIF(COTIZACIÓN!$D$15:$L$335,'BD GN'!CQ13,COTIZACIÓN!$L$15:$L$335) -> 0 | CT13: =SUMIF(COTIZACIÓN!$D$15:$O$335,'BD GN'!CQ13,COTIZACIÓN!$O$15:$O$335) -> 0 | CU13: =IFERROR(CT13/CS13,"0") -> 0
B14: PUERTA DOBLE BATIENTE LINEA PREMIUM TIPO EUROPEO SISTEMA VENECIA SERIE 40 | C14: PUERTA DOBLE BATIENTE LINEA PREMIUM TIPO EUROPEO VENECIA FERMO | E14: MANIJA CREMONA ITALIANA | G14: COMPOSICION MONOLITICO TEMPLADO 6 MM INC | Z14: INCLUYE DIVISORES | CB14: =C14 -> PUERTA DOBLE BATIENTE LINEA PREMIUM TIPO EUROPEO VENECIA FERMO | CQ14: =C14 -> PUERTA DOBLE BATIENTE LINEA PREMIUM TIPO EUROPEO VENECIA FERMO | CR14: LA | CS14: =SUMIF(COTIZACIÓN!$D$15:$L$335,'BD GN'!CQ14,COTIZACIÓN!$L$15:$L$335) -> 0 | CT14: =SUMIF(COTIZACIÓN!$D$15:$O$335,'BD GN'!CQ14,COTIZACIÓN!$O$15:$O$335) -> 0 | CU14: =IFERROR(CT14/CS14,"0") -> 0
B15: FACHADA FLOTANTE LINEA STICK SISTEMA SG45 TAPA Y PISAVIDRIO | C15: FACHADA FLOTANTE LINEA STICK SISTEMA SG45 TAPA Y PISAVIDRIO | E15: N.A | G15: COMPOSICION MONOLITICO TEMPLADO 5 MM INC | Z15: NO INCLUYE TUBO SUPERIOR | CB15: =C15 -> FACHADA FLOTANTE LINEA STICK SISTEMA SG45 TAPA Y PISAVIDRIO | CC15: 841900 | CD15: 614000 | CQ15: =C15 -> FACHADA FLOTANTE LINEA STICK SISTEMA SG45 TAPA Y PISAVIDRIO | CR15: LA | CS15: =SUMIF(COTIZACIÓN!$D$15:$L$335,'BD GN'!CQ15,COTIZACIÓN!$L$15:$L$335) -> 0 | CT15: =SUMIF(COTIZACIÓN!$D$15:$O$335,'BD GN'!CQ15,COTIZACIÓN!$O$15:$O$335) -> 0 | CU15: =IFERROR(CT15/CS15,"0") -> 0
B16: FACHADA ENTRE PLACAS LINEA STICK SISTEMA SG45 TAPA Y PISAVIDRIO | C16: FACHADA ENTRE PLACAS LINEA STICK SISTEMA SG45 TAPA Y PISAVIDRIO | E16: N.A | G16: COMPOSICION MONOLITICO TEMPLADO 4 MM INC | Z16: SISTEMA DE BARANDA EMBEBIDA, SE REQUIERE BOLSILLO CON PROFUNDIDAD MINIMA DE 15 CM, NO INCLUYE FIJACIÓN, SE ENTREGA INSTALADO Y LISTO PARA FIJAR, NO INCLUYE TUBO SUPERIOR | CB16: =C16 -> FACHADA ENTRE PLACAS LINEA STICK SISTEMA SG45 TAPA Y PISAVIDRIO | CC16: 841900 | CD16: 614000 | CQ16: =C16 -> FACHADA ENTRE PLACAS LINEA STICK SISTEMA SG45 TAPA Y PISAVIDRIO | CR16: LA | CS16: =SUMIF(COTIZACIÓN!$D$15:$L$335,'BD GN'!CQ16,COTIZACIÓN!$L$15:$L$335) -> 0 | CT16: =SUMIF(COTIZACIÓN!$D$15:$O$335,'BD GN'!CQ16,COTIZACIÓN!$O$15:$O$335) -> 0 | CU16: =IFERROR(CT16/CS16,"0") -> 0
B17: FACHADA FLOTANTE LINEA STICK SISTEMA SG45 PIEL DE VIDRIO | C17: FACHADA FLOTANTE LINEA STICK SISTEMA SG45 PIEL DE VIDRIO | E17: N.A | G17: COMPOSICION MONOLITICO CRUDO 6 MM INC | Z17: CON PERSIANA SGB0315 | CB17: =C17 -> FACHADA FLOTANTE LINEA STICK SISTEMA SG45 PIEL DE VIDRIO | CC17: 841900 | CD17: 614000 | CQ17: =C17 -> FACHADA FLOTANTE LINEA STICK SISTEMA SG45 PIEL DE VIDRIO | CR17: LA | CS17: =SUMIF(COTIZACIÓN!$D$15:$L$335,'BD GN'!CQ17,COTIZACIÓN!$L$15:$L$335) -> 0 | CT17: =SUMIF(COTIZACIÓN!$D$15:$O$335,'BD GN'!CQ17,COTIZACIÓN!$O$15:$O$335) -> 0 | CU17: =IFERROR(CT17/CS17,"0") -> 0
B18: FACHADA ENTRE PLACAS LINEA STICK SISTEMA SG45 PIEL DE VIDRIO | C18: FACHADA ENTRE PLACAS LINEA STICK SISTEMA SG45 PIEL DE VIDRIO | E18: N.A | G18: COMPOSICION MONOLITICO CRUDO 5 MM INC | CB18: =C18 -> FACHADA ENTRE PLACAS LINEA STICK SISTEMA SG45 PIEL DE VIDRIO | CC18: 841900 | CD18: 614000 | CQ18: =C18 -> FACHADA ENTRE PLACAS LINEA STICK SISTEMA SG45 PIEL DE VIDRIO | CR18: LA | CS18: =SUMIF(COTIZACIÓN!$D$15:$L$335,'BD GN'!CQ18,COTIZACIÓN!$L$15:$L$335) -> 0 | CT18: =SUMIF(COTIZACIÓN!$D$15:$O$335,'BD GN'!CQ18,COTIZACIÓN!$O$15:$O$335) -> 0 | CU18: =IFERROR(CT18/CS18,"0") -> 0
B19: CUERPO FIJO LINEA CLASSIC SISTEMA PRIMAVERA SERIE SG 4 | C19: CUERPO FIJO LINEA CLASSIC PRIMAVERA SIENA | E19: N.A | G19: COMPOSICION MONOLITICO CRUDO 4 MM MINI BOREAL | CB19: =C19 -> CUERPO FIJO LINEA CLASSIC PRIMAVERA SIENA | CC19: 455000 | CQ19: =C19 -> CUERPO FIJO LINEA CLASSIC PRIMAVERA SIENA | CR19: LA | CS19: =SUMIF(COTIZACIÓN!$D$15:$L$335,'BD GN'!CQ19,COTIZACIÓN!$L$15:$L$335) -> 0 | CT19: =SUMIF(COTIZACIÓN!$D$15:$O$335,'BD GN'!CQ19,COTIZACIÓN!$O$15:$O$335) -> 0 | CU19: =IFERROR(CT19/CS19,"0") -> 0
B20: CUERPO PROYECTANTE LINEA CLASSIC SISTEMA PRIMAVERA SERIE SG 4 | C20: CUERPO PROYECTANTE LINEA CLASSIC PRIMAVERA SIENA | E20: MANIJA LUJO BASIC | G20: COMPOSICION MONOLITICO CRUDO 4 MM INC | CB20: =C20 -> CUERPO PROYECTANTE LINEA CLASSIC PRIMAVERA SIENA | CC20: 455000 | CE20: 578000 | CQ20: =C20 -> CUERPO PROYECTANTE LINEA CLASSIC PRIMAVERA SIENA | CR20: LA | CS20: =SUMIF(COTIZACIÓN!$D$15:$L$335,'BD GN'!CQ20,COTIZACIÓN!$L$15:$L$335) -> 0 | CT20: =SUMIF(COTIZACIÓN!$D$15:$O$335,'BD GN'!CQ20,COTIZACIÓN!$O$15:$O$335) -> 0 | CU20: =IFERROR(CT20/CS20,"0") -> 0
B21: CUERPO BATIENTE LINEA CLASSIC SISTEMA PRIMAVERA SERIE SG 4 | C21: CUERPO BATIENTE LINEA CLASSIC PRIMAVERA SIENA | E21: MANIJA LUJO BASIC | G21: N.A. | CB21: =C21 -> CUERPO BATIENTE LINEA CLASSIC PRIMAVERA SIENA | CC21: 455000 | CE21: 578000 | CQ21: =C21 -> CUERPO BATIENTE LINEA CLASSIC PRIMAVERA SIENA | CR21: LA | CS21: =SUMIF(COTIZACIÓN!$D$15:$L$335,'BD GN'!CQ21,COTIZACIÓN!$L$15:$L$335) -> 0 | CT21: =SUMIF(COTIZACIÓN!$D$15:$O$335,'BD GN'!CQ21,COTIZACIÓN!$O$15:$O$335) -> 0 | CU21: =IFERROR(CT21/CS21,"0") -> 0
B22: PUERTA BATIENTE LINEA CLASSIC SISTEMA PRIMAVERA SERIE SG 4 | C22: PUERTA BATIENTE LINEA CLASSIC PRIMAVERA SIENA | E22: MANIJA LUJO BASIC | CB22: =C22 -> PUERTA BATIENTE LINEA CLASSIC PRIMAVERA SIENA | CC22: 455000 | CQ22: =C22 -> PUERTA BATIENTE LINEA CLASSIC PRIMAVERA SIENA | CR22: LA | CS22: =SUMIF(COTIZACIÓN!$D$15:$L$335,'BD GN'!CQ22,COTIZACIÓN!$L$15:$L$335) -> 0 | CT22: =SUMIF(COTIZACIÓN!$D$15:$O$335,'BD GN'!CQ22,COTIZACIÓN!$O$15:$O$335) -> 0 | CU22: =IFERROR(CT22/CS22,"0") -> 0
B23: CUERPO FIJO LINEA CLASSIC SISTEMA PRIMAVERA SERIE SG 3 | C23: CUERPO FIJO LINEA CLASSIC SISTEMA PRIMAVERA SERIE SG 3 | E23: N.A | CB23: =C23 -> CUERPO FIJO LINEA CLASSIC SISTEMA PRIMAVERA SERIE SG 3 | CQ23: =C23 -> CUERPO FIJO LINEA CLASSIC SISTEMA PRIMAVERA SERIE SG 3 | CR23: LA | CS23: =SUMIF(COTIZACIÓN!$D$15:$L$335,'BD GN'!CQ23,COTIZACIÓN!$L$15:$L$335) -> 0 | CT23: =SUMIF(COTIZACIÓN!$D$15:$O$335,'BD GN'!CQ23,COTIZACIÓN!$O$15:$O$335) -> 0 | CU23: =IFERROR(CT23/CS23,"0") -> 0
B24: SISTEMA REJILLA | C24: SISTEMA REJILLA | E24: N.A | CB24: =C24 -> SISTEMA REJILLA | CQ24: =C24 -> SISTEMA REJILLA | CR24: LA | CS24: =SUMIF(COTIZACIÓN!$D$15:$L$335,'BD GN'!CQ24,COTIZACIÓN!$L$15:$L$335) -> 0 | CT24: =SUMIF(COTIZACIÓN!$D$15:$O$335,'BD GN'!CQ24,COTIZACIÓN!$O$15:$O$335) -> 0 | CU24: =IFERROR(CT24/CS24,"0") -> 0
B25: PUERTA CORREDIZA CON ACCESIORIOS INOX | C25: PUERTA CORREDIZA CON ACCESIORIOS INOX | E25: MANIJA INOX | CB25: =C25 -> PUERTA CORREDIZA CON ACCESIORIOS INOX | CQ25: =C25 -> PUERTA CORREDIZA CON ACCESIORIOS INOX | CR25: LI | CS25: =SUMIF(COTIZACIÓN!$D$15:$L$335,'BD GN'!CQ25,COTIZACIÓN!$L$15:$L$335) -> 0 | CT25: =SUMIF(COTIZACIÓN!$D$15:$O$335,'BD GN'!CQ25,COTIZACIÓN!$O$15:$O$335) -> 0 | CU25: =IFERROR(CT25/CS25,"0") -> 0
B26: CUERPO FIJO CON ACCESORIOS INOX | C26: CUERPO FIJO CON ACCESORIOS INOX | E26: N.A | CB26: =C26 -> CUERPO FIJO CON ACCESORIOS INOX | CQ26: =C26 -> CUERPO FIJO CON ACCESORIOS INOX | CR26: LI | CS26: =SUMIF(COTIZACIÓN!$D$15:$L$335,'BD GN'!CQ26,COTIZACIÓN!$L$15:$L$335) -> 0 | CT26: =SUMIF(COTIZACIÓN!$D$15:$O$335,'BD GN'!CQ26,COTIZACIÓN!$O$15:$O$335) -> 0 | CU26: =IFERROR(CT26/CS26,"0") -> 0
B27: PUERTA BATIENTE CON ACCESORIOS INOX | C27: PUERTA BATIENTE CON ACCESORIOS INOX | E27: MANIJA INOX | CB27: =C27 -> PUERTA BATIENTE CON ACCESORIOS INOX | CQ27: =C27 -> PUERTA BATIENTE CON ACCESORIOS INOX | CR27: LI | CS27: =SUMIF(COTIZACIÓN!$D$15:$L$335,'BD GN'!CQ27,COTIZACIÓN!$L$15:$L$335) -> 0 | CT27: =SUMIF(COTIZACIÓN!$D$15:$O$335,'BD GN'!CQ27,COTIZACIÓN!$O$15:$O$335) -> 0 | CU27: =IFERROR(CT27/CS27,"0") -> 0
B28: PUERTA DOBLE BATIENTE CON ACCESORIOS INOX | C28: PUERTA DOBLE BATIENTE CON ACCESORIOS INOX | E28: MANIJA INOX | CB28: =C28 -> PUERTA DOBLE BATIENTE CON ACCESORIOS INOX | CQ28: =C28 -> PUERTA DOBLE BATIENTE CON ACCESORIOS INOX | CR28: LI | CS28: =SUMIF(COTIZACIÓN!$D$15:$L$335,'BD GN'!CQ28,COTIZACIÓN!$L$15:$L$335) -> 0 | CT28: =SUMIF(COTIZACIÓN!$D$15:$O$335,'BD GN'!CQ28,COTIZACIÓN!$O$15:$O$335) -> 0 | CU28: =IFERROR(CT28/CS28,"0") -> 0
B29: DIVISIONES DE BAÑO CON ACCESORIOS EN ACERO INOXIDABLE | C29: DIVISIONES DE BAÑO CON ACCESORIOS EN ACERO INOXIDABLE | E29: N.A | CB29: =C29 -> DIVISIONES DE BAÑO CON ACCESORIOS EN ACERO INOXIDABLE | CC29: 390000 | CQ29: =C29 -> DIVISIONES DE BAÑO CON ACCESORIOS EN ACERO INOXIDABLE | CR29: LI | CS29: =SUMIF(COTIZACIÓN!$D$15:$L$335,'BD GN'!CQ29,COTIZACIÓN!$L$15:$L$335) -> 0 | CT29: =SUMIF(COTIZACIÓN!$D$15:$O$335,'BD GN'!CQ29,COTIZACIÓN!$O$15:$O$335) -> 0 | CU29: =IFERROR(CT29/CS29,"0") -> 0
B30: PUERTA CORREDIZA LINEA PREMIUM TIPO EUROPEO SISTEMA VENECIA SERIE 70 TIPO POKET | C30: PUERTA CORREDIZA LINEA PREMIUM TIPO EUROPEO VENECIA NAPOLES TIPO POKET | E30: CERRADURA MULTI-PUNTO MANIJA ITALIANA | CB30: =C30 -> PUERTA CORREDIZA LINEA PREMIUM TIPO EUROPEO VENECIA NAPOLES TIPO POKET | CC30: 576000 | CD30: 539000 | CE30: 777000 | CQ30: =C30 -> PUERTA CORREDIZA LINEA PREMIUM TIPO EUROPEO VENECIA NAPOLES TIPO POKET | CR30: LA | CS30: =SUMIF(COTIZACIÓN!$D$15:$L$335,'BD GN'!CQ30,COTIZACIÓN!$L$15:$L$335) -> 0 | CT30: =SUMIF(COTIZACIÓN!$D$15:$O$335,'BD GN'!CQ30,COTIZACIÓN!$O$15:$O$335) -> 0 | CU30: =IFERROR(CT30/CS30,"0") -> 0
B31: PUERTA CORREDIZA LINEA CLASSIC SISTEMA 8025 | C31: PUERTA CORREDIZA LINEA CLASSIC SISTEMA 8025 | E31: CIERRE EMBUTIDO DE IMPACTO | CB31: =C31 -> PUERTA CORREDIZA LINEA CLASSIC SISTEMA 8025 | CQ31: =C31 -> PUERTA CORREDIZA LINEA CLASSIC SISTEMA 8025 | CR31: LA | CS31: =SUMIF(COTIZACIÓN!$D$15:$L$335,'BD GN'!CQ31,COTIZACIÓN!$L$15:$L$335) -> 0 | CT31: =SUMIF(COTIZACIÓN!$D$15:$O$335,'BD GN'!CQ31,COTIZACIÓN!$O$15:$O$335) -> 0 | CU31: =IFERROR(CT31/CS31,"0") -> 0
B32: N.A | C32: N.A | E32: N.A | CB32: =C32 -> N.A | CQ32: =C32 -> N.A | CR32: LI | CS32: =SUMIF(COTIZACIÓN!$D$15:$L$335,'BD GN'!CQ32,COTIZACIÓN!$L$15:$L$335) -> 0 | CT32: =SUMIF(COTIZACIÓN!$D$15:$O$335,'BD GN'!CQ32,COTIZACIÓN!$O$15:$O$335) -> 0 | CU32: =IFERROR(CT32/CS32,"0") -> 0
B33: CUERPO PROYECTANTE LINEA CLASSIC SISTEMA 3831 | C33: CUERPO PROYECTANTE LINEA CLASSIC SISTEMA 3831 | E33: MANIJA LUJO BASIC | CB33: =C33 -> CUERPO PROYECTANTE LINEA CLASSIC SISTEMA 3831 | CQ33: =C33 -> CUERPO PROYECTANTE LINEA CLASSIC SISTEMA 3831 | CR33: LA | CS33: =SUMIF(COTIZACIÓN!$D$15:$L$335,'BD GN'!CQ33,COTIZACIÓN!$L$15:$L$335) -> 0 | CT33: =SUMIF(COTIZACIÓN!$D$15:$O$335,'BD GN'!CQ33,COTIZACIÓN!$O$15:$O$335) -> 0 | CU33: =IFERROR(CT33/CS33,"0") -> 0
B34: CUERPO FIJO LINEA CLASSIC SISTEMA 3831 | C34: CUERPO FIJO LINEA CLASSIC SISTEMA 3831 | E34: N.A | CB34: =C34 -> CUERPO FIJO LINEA CLASSIC SISTEMA 3831 | CQ34: =C34 -> CUERPO FIJO LINEA CLASSIC SISTEMA 3831 | CR34: LA | CS34: =SUMIF(COTIZACIÓN!$D$15:$L$335,'BD GN'!CQ34,COTIZACIÓN!$L$15:$L$335) -> 0 | CT34: =SUMIF(COTIZACIÓN!$D$15:$O$335,'BD GN'!CQ34,COTIZACIÓN!$O$15:$O$335) -> 0 | CU34: =IFERROR(CT34/CS34,"0") -> 0
B35: BARANDA EMBEBIDA SIN TUBO SUPERIOR | C35: BARANDA EMBEBIDA SIN TUBO SUPERIOR | E35: N.A | CB35: =C35 -> BARANDA EMBEBIDA SIN TUBO SUPERIOR | CC35: 456000 | CE35: 474000 | CQ35: =C35 -> BARANDA EMBEBIDA SIN TUBO SUPERIOR | CR35: LI | CS35: =SUMIF(COTIZACIÓN!$D$15:$L$335,'BD GN'!CQ35,COTIZACIÓN!$L$15:$L$335) -> 0 | CT35: =SUMIF(COTIZACIÓN!$D$15:$O$335,'BD GN'!CQ35,COTIZACIÓN!$O$15:$O$335) -> 0 | CU35: =IFERROR(CT35/CS35,"0") -> 0
B36: BARANDA EMBEBIDA CON TUBO SUPERIOR EN INOX | C36: BARANDA EMBEBIDA CON TUBO SUPERIOR EN INOX | E36: N.A | CB36: =C36 -> BARANDA EMBEBIDA CON TUBO SUPERIOR EN INOX | CC36: 456000 | CQ36: =C36 -> BARANDA EMBEBIDA CON TUBO SUPERIOR EN INOX | CR36: LI | CS36: =SUMIF(COTIZACIÓN!$D$15:$L$335,'BD GN'!CQ36,COTIZACIÓN!$L$15:$L$335) -> 0 | CT36: =SUMIF(COTIZACIÓN!$D$15:$O$335,'BD GN'!CQ36,COTIZACIÓN!$O$15:$O$335) -> 0 | CU36: =IFERROR(CT36/CS36,"0") -> 0
B37: BARANDA EMBEBIDA CON TUBO SUPERIOR EN ALUMINIO SG | C37: BARANDA EMBEBIDA CON TUBO SUPERIOR EN ALUMINIO SG | E37: N.A | CB37: =C37 -> BARANDA EMBEBIDA CON TUBO SUPERIOR EN ALUMINIO SG | CC37: 456000 | CQ37: =C37 -> BARANDA EMBEBIDA CON TUBO SUPERIOR EN ALUMINIO SG | CR37: LI | CS37: =SUMIF(COTIZACIÓN!$D$15:$L$335,'BD GN'!CQ37,COTIZACIÓN!$L$15:$L$335) -> 0 | CT37: =SUMIF(COTIZACIÓN!$D$15:$O$335,'BD GN'!CQ37,COTIZACIÓN!$O$15:$O$335) -> 0 | CU37: =IFERROR(CT37/CS37,"0") -> 0
B38: BARANDILLA CON TUBO SUPERIOR EN INOX | C38: BARANDILLA CON TUBO SUPERIOR EN INOX | E38: N.A | CB38: =C38 -> BARANDILLA CON TUBO SUPERIOR EN INOX | CC38: 339150 | CQ38: =C38 -> BARANDILLA CON TUBO SUPERIOR EN INOX | CR38: LI | CS38: =SUMIF(COTIZACIÓN!$D$15:$L$335,'BD GN'!CQ38,COTIZACIÓN!$L$15:$L$335) -> 0 | CT38: =SUMIF(COTIZACIÓN!$D$15:$O$335,'BD GN'!CQ38,COTIZACIÓN!$O$15:$O$335) -> 0 | CU38: =IFERROR(CT38/CS38,"0") -> 0
B39: BARANDILLA SIN TUBO SUPERIOR | C39: BARANDILLA SIN TUBO SUPERIOR | E39: N.A | CB39: =C39 -> BARANDILLA SIN TUBO SUPERIOR | CC39: 339150 | CQ39: =C39 -> BARANDILLA SIN TUBO SUPERIOR | CR39: LI | CS39: =SUMIF(COTIZACIÓN!$D$15:$L$335,'BD GN'!CQ39,COTIZACIÓN!$L$15:$L$335) -> 0 | CT39: =SUMIF(COTIZACIÓN!$D$15:$O$335,'BD GN'!CQ39,COTIZACIÓN!$O$15:$O$335) -> 0 | CU39: =IFERROR(CT39/CS39,"0") -> 0
B40: BARANDA DE APLIQUE CON ACCESORIOS INOX SIN TUBO SUPERIOR | C40: BARANDA DE APLIQUE CON ACCESORIOS INOX SIN TUBO SUPERIOR | E40: N.A | CB40: =C40 -> BARANDA DE APLIQUE CON ACCESORIOS INOX SIN TUBO SUPERIOR | CC40: 475000 | CQ40: =C40 -> BARANDA DE APLIQUE CON ACCESORIOS INOX SIN TUBO SUPERIOR | CR40: LI | CS40: =SUMIF(COTIZACIÓN!$D$15:$L$335,'BD GN'!CQ40,COTIZACIÓN!$L$15:$L$335) -> 0 | CT40: =SUMIF(COTIZACIÓN!$D$15:$O$335,'BD GN'!CQ40,COTIZACIÓN!$O$15:$O$335) -> 0 | CU40: =IFERROR(CT40/CS40,"0") -> 0
...

Sheet BD P&G
B2: CONSTRUCTOR Y RESIDENCIAL PREMIUM | H2: CONSTRUCTOR Y RESIDENCIAL CLASSIC
B4: GASTOS DE VENTA | H4: GASTOS DE VENTA
B5: RUBRO | C5: =SUM(C7:C11) -> 21966430 | D5: =SUM(D7:D11) -> 263597160 | E5: =SUM(E7:E11) -> 0.026359716 | F5: OBSERVACIONES | H5: RUBRO | I5: =SUM(I7:I11) -> 6666666.7 | J5: =SUM(J7:J11) -> 80000000 | K5: =SUM(K7:K11) -> 0.02 | L5: OBSERVACIONES
C6: VR MES | D6: VR ANUAL | E6: % PESO PP | I6: VR MES | J6: VR ANUAL | K6: % PESO PP
B7: GASTOS DE PERSONAL | C7: 17866430 | D7: =C7*12 -> 214397160 | E7: =D7/$N$7 -> 0.021439716 | H7: GASTOS DE PERSONAL | I7: 0 | J7: 0 | K7: 0 | N7: 10000000000
B8: COMISIONES | C8: 0 | D8: =C8*12 -> 0 | E8: =D8/$N$7 -> 0 | H8: COMISIONES | I8: 6666666.7 | J8: 80000000 | K8: 0.02
B9: MANTENIMIENTOS VEHICULO | C9: 1100000 | D9: =C9*12 -> 13200000 | E9: =D9/$N$7 -> 0.00132 | H9: MANTENIMIENTOS VEHICULO | I9: 0 | J9: 0 | K9: 0
B10: GASTOS DE VIAJE | C10: 2000000 | D10: =C10*12 -> 24000000 | E10: =D10/$N$7 -> 0.0024 | H10: GASTOS DE VIAJE | I10: 0 | J10: 0 | K10: 0
B11: DIVERSOS (PUBLICIDAD Y MERCADEO | C11: 1000000 | D11: =C11*12 -> 12000000 | E11: =D11/$N$7 -> 0.0012 | H11: DIVERSOS (PUBLICIDAD Y MERCADEO | I11: 0 | J11: 0 | K11: 0
B13: GASTOS ADM | H13: GASTOS ADM
B14: RUBRO | C14: =SUM(C16:C23) -> 22654530 | D14: =SUM(D16:D23) -> 271854360 | E14: =SUM(E16:E23) -> 0.027185436 | F14: OBSERVACIONES | H14: RUBRO | I14: =SUM(I16:I23) -> 0 | J14: =SUM(J16:J23) -> 0 | K14: =SUM(K16:K23) -> 0 | L14: OBSERVACIONES
C15: VR MES | D15: VR ANUAL | E15: % PESO PP | I15: VR MES | J15: VR ANUAL | K15: % PESO PP
B16: GASTOS DE PERSONAL | C16: 6454081 | D16: =C16*12 -> 77448972 | E16: =D16/$N$7 -> 0.0077448972 | F16: AUX CONTABLE | H16: GASTOS DE PERSONAL | I16: 0 | J16: 0 | K16: 0 | L16: AUX CONTABLE
B17: HONORARIOS | C17: 10172000 | D17: =C17*12 -> 122064000 | E17: =D17/$N$7 -> 0.0122064 | H17: HONORARIOS | I17: 0 | J17: 0 | K17: 0
B18: ARRENDAMIENTOS | C18: 2299028 | D18: =C18*12 -> 27588336 | E18: =D18/$N$7 -> 0.0027588336 | H18: ARRENDAMIENTOS | I18: 0 | J18: 0 | K18: 0
B19: SERVICIOS | C19: 688315 | D19: =C19*12 -> 8259780 | E19: =D19/$N$7 -> 0.000825978 | H19: SERVICIOS | I19: 0 | J19: 0 | K19: 0
B20: SEGUROS | C20: 2596106 | D20: =C20*12 -> 31153272 | E20: =D20/$N$7 -> 0.0031153272 | H20: SEGUROS | I20: 0 | J20: 0 | K20: 0
B21: DIVERSOS | C21: 445000 | D21: =C21*12 -> 5340000 | E21: =D21/$N$7 -> 0.000534 | H21: DIVERSOS | I21: 0 | J21: 0 | K21: 0
B22: GASTOS LEGALES | C22: 0 | D22: =C22*12 -> 0 | E22: =D22/$N$7 -> 0 | H22: GASTOS LEGALES | I22: 0 | J22: 0 | K22: 0
B23: ADECUACION E INSTALACION | C23: 0 | D23: =C23*12 -> 0 | E23: =D23/$N$7 -> 0 | H23: ADECUACION E INSTALACION | I23: 0 | J23: 0 | K23: 0
B25: COSTOS INDIRECTOS | H25: COSTOS INDIRECTOS
B26: RUBRO | C26: =SUM(C28:C39) -> 49162117 | D26: =SUM(D28:D39) -> 589945404 | E26: =SUM(E28:E39) -> 0.05899454 | F26: OBSERVACIONES | H26: RUBRO | I26: =SUM(I28:I39) -> 18487784 | J26: =SUM(J28:J39) -> 2.2185341e+08 | K26: =SUM(K28:K39) -> 0.055463352 | L26: OBSERVACIONES
C27: VR MES | D27: VR ANUAL | E27: % PESO PP | I27: VR MES | J27: VR ANUAL | K27: % PESO PP
B28: HONORARIOS ENSAMBLE | C28: 17617879 | D28: =C28*12 -> 211414548 | E28: =D28/$N$7 -> 0.021141455 | F28: SE COMPARA CON COTIZACION | H28: HONORARIOS ENSAMBLE | I28: 12960215 | J28: 1.5552259e+08 | K28: 0.038880646 | L28: SE COMPARA CON COTIZACION
B29: HONORARIOS INSTALACION | C29: 4874425 | D29: =C29*12 -> 58493100 | E29: =D29/$N$7 -> 0.00584931 | H29: HONORARIOS INSTALACION | I29: 2490084.8 | J29: 29881018 | K29: 0.0074702545
B30: HONORARIOS TECNICOS | C30: 17649293 | D30: =C30*12 -> 211791516 | E30: =D30/$N$7 -> 0.021179152
B31: FLETES, TRANSPORTE Y ACARREOS | C31: 0 | D31: =C31*12 -> 0 | E31: =D31/$N$7 -> 0 | F31: COTIZACION | H31: FLETES, TRANSPORTE Y ACARREOS | I31: 0 | J31: 0 | K31: 0 | L31: COTIZACION
B32: ARRENDAMIENTOS | C32: 756250 | D32: =C32*12 -> 9075000 | E32: =D32/$N$7 -> 0.0009075 | H32: ARRENDAMIENTOS | I32: 0 | J32: 0 | K32: 0
B33: SERVICIOS | C33: 1175200 | D33: =C33*12 -> 14102400 | E33: =D33/$N$7 -> 0.00141024 | H33: SERVICIOS | I33: 0 | J33: 0 | K33: 0
B34: MANTENIMIENTO Y REPARACIONES | C34: 400000 | D34: =C34*12 -> 4800000 | E34: =D34/$N$7 -> 0.00048
B35: DEPRECIACION | C35: 4411462 | D35: =C35*12 -> 52937544 | E35: =D35/$N$7 -> 0.0052937544 | H35: DEPRECIACION | I35: 0 | J35: 0 | K35: 0
B36: COMBUSTIBLES | C36: 1400000 | D36: =C36*12 -> 16800000 | E36: =D36/$N$7 -> 0.00168 | H36: COMBUSTIBLES | I36: 1341816 | J36: 16101792 | K36: 0.004025448
B37: UTENSILIOS SST | C37: 877608 | D37: =C37*12 -> 10531296 | E37: =D37/$N$7 -> 0.0010531296 | H37: UTENSILIOS SST | I37: 1695667.6 | J37: 20348011 | K37: 0.0050870027
B38: GASTOS DE REPRESENTACION | C38: 0 | D38: =C38*12 -> 0 | E38: =D38/$N$7 -> 0
B39: EMPAQUE Y CINTA PROTECCION | C39: 0 | D39: =C39*12 -> 0 | E39: =D39/$N$7 -> 0 | F39: COTIZACION | H39: EMPAQUE Y CINTA PROTECCION | I39: 0 | J39: 0 | K39: 0
B41: IMPUESTOS | H41: IMPUESTOS
B42: RUBRO | C42: =SUM(C44:C52) -> 4650000 | D42: =SUM(D44:D52) -> 55800000 | E42: =SUM(E44:E52) -> 0.00558 | F42: OBSERVACIONES | H42: RUBRO | I42: =SUM(I44:I52) -> 2000000 | J42: =SUM(J44:J52) -> 24000000 | K42: =SUM(K44:K52) -> 0.004 | L42: OBSERVACIONES
C43: VR MES | D43: VR ANUAL | E43: % PESO PP | I43: VR MES | J43: VR ANUAL | K43: % PESO PP
B44: INDUSTRIA Y COMERCIO | C44: 4400000 | D44: =C44*12 -> 52800000 | E44: =D44/$N$7 -> 0.00528 | H44: INDUSTRIA Y COMERCIO | I44: 2000000 | J44: 24000000 | K44: 0.004
B45: CAMARA DE COMERCIO | C45: 250000 | D45: =C45*12 -> 3000000 | E45: =D45/$N$7 -> 0.0003 | H45: CAMARA DE COMERCIO | I45: 0 | J45: 0 | K45: 0

Sheet BD M.O
D1: INCREMENTO MANO DE OBRA | E1: 0.2
B2: Ventaneria | C2: SISTEMA | D2: Concepto | E2: Intalación (m2) | F2: Ensamble (2h) | G2: Ensamble (3h) | H2: Ensamble (4h) | I2: Hoja Adic | K2: Intalación (m2) | L2: Ensamble (2h) | M2: Ensamble (3h) | N2: Ensamble (4h) | O2: Hoja Adic
B3: Ventanas y Puertas Corredizas | C3: VENTANA CORREDIZA LINEA TRADICIONAL SISTEMA SG 5020 | D3: Incluye: Lucetas, alfajias, tubulares, cristal, armada de marcos, recibidores y/o seguros. | E3: =+K3+(K3*$E$1) -> 38640 | F3: =+L3+(L3*$E$1) -> 18000 | G3: =+M3+(M3*$E$1) -> 26400 | H3: =+N3+(N3*$E$1) -> 30000 | I3: =+O3+(O3*$E$1) -> 9600 | K3: 32200 | L3: 15000 | M3: 22000 | N3: 25000 | O3: 8000
C4: VENTANA CORREDIZA LINEA TRADICIONAL SISTEMA SG 744 | E4: =+K4+(K4*$E$1) -> 38640 | F4: =+L4+(L4*$E$1) -> 18000 | G4: =+M4+(M4*$E$1) -> 26400 | H4: =+N4+(N4*$E$1) -> 31200 | I4: =+O4+(O4*$E$1) -> 9600 | K4: 32200 | L4: 15000 | M4: 22000 | N4: 26000 | O4: 8000
C5: PUERTA CORREDIZA LINEA TRADICIONAL SISTEMA SG 744 | E5: =+K5+(K5*$E$1) -> 38640 | F5: =+L5+(L5*$E$1) -> 42000 | G5: =+M5+(M5*$E$1) -> 54000 | H5: =+N5+(N5*$E$1) -> 66000 | I5: =+O5+(O5*$E$1) -> 9600 | K5: 32200 | L5: 35000 | M5: 45000 | N5: 55000 | O5: 8000
C6: VENTANA CORREDIZA LINEA TRADICIONAL SISTEMA SG 8025 | E6: =+K6+(K6*$E$1) -> 38640 | F6: =+L6+(L6*$E$1) -> 36000 | G6: =+M6+(M6*$E$1) -> 48000 | H6: =+N6+(N6*$E$1) -> 60000 | I6: =+O6+(O6*$E$1) -> 10800 | K6: 32200 | L6: 30000 | M6: 40000 | N6: 50000 | O6: 9000
C7: PUERTA CORREDIZA LINEA TRADICIONAL SISTEMA SG 8025 | E7: =+K7+(K7*$E$1) -> 38640 | F7: =+L7+(L7*$E$1) -> 42000 | G7: =+M7+(M7*$E$1) -> 54000 | H7: =+N7+(N7*$E$1) -> 66000 | I7: =+O7+(O7*$E$1) -> 10800 | K7: 32200 | L7: 35000 | M7: 45000 | N7: 55000 | O7: 9000
C8: PUERTA CORREDIZA LINEA TRADICIONAL SISTEMA SG 7038 | E8: =+K8+(K8*$E$1) -> 38640 | F8: =+L8+(L8*$E$1) -> 66000 | G8: =+M8+(M8*$E$1) -> 78000 | H8: =+N8+(N8*$E$1) -> 90000 | I8: =+O8+(O8*$E$1) -> 12000 | K8: 32200 | L8: 55000 | M8: 65000 | N8: 75000 | O8: 10000
C9: VENTANA CORREDIZA LINEA CLASSIC SISTEMA PRIMAVERA SERIE SG 3 | E9: =+K9+(K9*$E$1) -> 38640 | F9: =+L9+(L9*$E$1) -> 22800 | G9: =+M9+(M9*$E$1) -> 26400 | H9: =+N9+(N9*$E$1) -> 31200 | I9: =+O9+(O9*$E$1) -> 9600 | K9: 32200 | L9: 19000 | M9: 22000 | N9: 26000 | O9: 8000
C10: VENTANA CORREDIZA LINEA CLASSIC PRIMAVERA LAGO | E10: =+K10+(K10*$E$1) -> 38640 | F10: =+L10+(L10*$E$1) -> 22800 | G10: =+M10+(M10*$E$1) -> 26400 | H10: =+N10+(N10*$E$1) -> 31200 | I10: =+O10+(O10*$E$1) -> 9600 | K10: 32200 | L10: 19000 | M10: 22000 | N10: 26000 | O10: 8000
C11: PUERTA CORREDIZA LINEA CLASSIC PRIMAVERA LAGO | E11: =+K11+(K11*$E$1) -> 38640 | F11: =+L11+(L11*$E$1) -> 30000 | G11: =+M11+(M11*$E$1) -> 32400 | H11: =+N11+(N11*$E$1) -> 39600 | I11: =+O11+(O11*$E$1) -> 10800 | K11: 32200 | L11: 25000 | M11: 27000 | N11: 33000 | O11: 9000
C12: PUERTA CORREDIZA LINEA CLASSIC PRIMAVERA LUCCA | E12: =+K12+(K12*$E$1) -> 38640 | F12: =+L12+(L12*$E$1) -> 26400 | G12: =+M12+(M12*$E$1) -> 32400 | H12: =+N12+(N12*$E$1) -> 39600 | I12: =+O12+(O12*$E$1) -> 10800 | K12: 32200 | L12: 22000 | M12: 27000 | N12: 33000 | O12: 9000
C13: PUERTA CORREDIZA LINEA CLASSIC SISTEMA 8025 | E13: =+K13+(K13*$E$1) -> 38640 | F13: =+L13+(L13*$E$1) -> 26400 | G13: =+M13+(M13*$E$1) -> 32400 | H13: =+N13+(N13*$E$1) -> 39600 | I13: =+O13+(O13*$E$1) -> 10800 | K13: 32200 | L13: 22000 | M13: 27000 | N13: 33000 | O13: 9000
C14: VENTANA CORREDIZA LINEA PREMIUM EUROPEO SISTEMA LSA 9060 | E14: =+K14+(K14*$E$1) -> 38640 | F14: =+L14+(L14*$E$1) -> 26400 | G14: =+M14+(M14*$E$1) -> 32400 | H14: =+N14+(N14*$E$1) -> 39600 | I14: =+O14+(O14*$E$1) -> 10800 | K14: 32200 | L14: 22000 | M14: 27000 | N14: 33000 | O14: 9000
C15: VENTANA CORREDIZA LINEA PREMIUM TIPO EUROPEO VENECIA MONZA | E15: =+K15+(K15*$E$1) -> 38640 | F15: =+L15+(L15*$E$1) -> 26400 | G15: =+M15+(M15*$E$1) -> 32400 | H15: =+N15+(N15*$E$1) -> 39600 | I15: =+O15+(O15*$E$1) -> 10800 | K15: 32200 | L15: 22000 | M15: 27000 | N15: 33000 | O15: 9000
B16: Ventanas Proyectantes | C16: CUERPO PROYECTANTE LINEA PREMIUM TIPO EUROPEO VENECIA FERMO | D16: Sistemas combinados de naves y fijos, Incluye cuadre de accesorios. | E16: =+K16+(K16*$E$1) -> 38640 | F16: =+L16+(L16*$E$1) -> 26400 | G16: =+M16+(M16*$E$1) -> 31200 | H16: =+N16+(N16*$E$1) -> 36000 | I16: =+O16+(O16*$E$1) -> 10800 | K16: 32200 | L16: 22000 | M16: 26000 | N16: 30000 | O16: 9000
C17: CUERPO BATIENTE LINEA PREMIUM TIPO EUROPEO VENECIA FERMO | E17: =+K17+(K17*$E$1) -> 38640 | F17: =+L17+(L17*$E$1) -> 26400 | G17: =+M17+(M17*$E$1) -> 31200 | H17: =+N17+(N17*$E$1) -> 36000 | I17: =+O17+(O17*$E$1) -> 10800 | K17: 32200 | L17: 22000 | M17: 26000 | N17: 30000 | O17: 9000
C18: CUERPO PROYECTANTE LINEA PREMIUM EUROPEO SISTEMA LSA 0932 | E18: =+K18+(K18*$E$1) -> 38640 | F18: =+L18+(L18*$E$1) -> 26400 | G18: =+M18+(M18*$E$1) -> 31200 | H18: =+N18+(N18*$E$1) -> 36000 | I18: =+O18+(O18*$E$1) -> 10800 | K18: 32200 | L18: 22000 | M18: 26000 | N18: 30000 | O18: 9000
C19: CUERPO BATIENTE LINEA CLASSIC PRIMAVERA SIENA | E19: =+K19+(K19*$E$1) -> 38640 | F19: =+L19+(L19*$E$1) -> 26400 | G19: =+M19+(M19*$E$1) -> 31200 | H19: =+N19+(N19*$E$1) -> 36000 | I19: =+O19+(O19*$E$1) -> 10800 | K19: 32200 | L19: 22000 | M19: 26000 | N19: 30000 | O19: 9000
C20: CUERPO PROYECTANTE LINEA CLASSIC PRIMAVERA SIENA | E20: =+K20+(K20*$E$1) -> 38640 | F20: =+L20+(L20*$E$1) -> 26400 | G20: =+M20+(M20*$E$1) -> 31200 | H20: =+N20+(N20*$E$1) -> 36000 | I20: =+O20+(O20*$E$1) -> 10800 | K20: 32200 | L20: 22000 | M20: 26000 | N20: 30000 | O20: 9000
C21: CUERPO PROYECTANTE LINEA CLASSIC SISTEMA 3831 | E21: =+K21+(K21*$E$1) -> 38640 | F21: =+L21+(L21*$E$1) -> 42000 | G21: =+M21+(M21*$E$1) -> 48000 | H21: =+N21+(N21*$E$1) -> 54000 | I21: =+O21+(O21*$E$1) -> 10800 | K21: 32200 | L21: 35000 | M21: 40000 | N21: 45000 | O21: 9000
B22: Ventanas Fijas | C22: CUERPO FIJO LINEA PREMIUM TIPO EUROPEO VENECIA FERMO | D22: Incluye: Lucetas, alfajias, tubulares, cristal, armada de marcos, recibidores y/o seguros. Hasta 3 m2 | E22: =+K22+(K22*$E$1) -> 38640 | F22: =+L22+(L22*$E$1) -> 16800 | G22: =+M22+(M22*$E$1) -> 21600 | H22: =+N22+(N22*$E$1) -> 26400 | I22: =+O22+(O22*$E$1) -> 10800 | K22: 32200 | L22: 14000 | M22: 18000 | N22: 22000 | O22: 9000
C23: CUERPO FIJO LINEA CLASSIC PRIMAVERA SIENA | E23: =+K23+(K23*$E$1) -> 38640 | F23: =+L23+(L23*$E$1) -> 16800 | G23: =+M23+(M23*$E$1) -> 21600 | H23: =+N23+(N23*$E$1) -> 26400 | I23: =+O23+(O23*$E$1) -> 10800 | K23: 32200 | L23: 14000 | M23: 18000 | N23: 22000 | O23: 9000
C24: CUERPO FIJO TUBULAR SG | E24: =+K24+(K24*$E$1) -> 38640 | F24: =+L24+(L24*$E$1) -> 16800 | G24: =+M24+(M24*$E$1) -> 21600 | H24: =+N24+(N24*$E$1) -> 26400 | I24: =+O24+(O24*$E$1) -> 10800 | K24: 32200 | L24: 14000 | M24: 18000 | N24: 22000 | O24: 9000
C25: CUERPO FIJO LINEA PREMIUM EUROPEO SISTEMA LSA 0932 | E25: =+K25+(K25*$E$1) -> 38640 | F25: =+L25+(L25*$E$1) -> 16800 | G25: =+M25+(M25*$E$1) -> 21600 | H25: =+N25+(N25*$E$1) -> 26400 | I25: =+O25+(O25*$E$1) -> 10800 | K25: 32200 | L25: 14000 | M25: 18000 | N25: 22000 | O25: 9000
C26: CUERPO FIJO LINEA CLASSIC SISTEMA PRIMAVERA SERIE SG 3 | E26: =+K26+(K26*$E$1) -> 38640 | F26: =+L26+(L26*$E$1) -> 16800 | G26: =+M26+(M26*$E$1) -> 21600 | H26: =+N26+(N26*$E$1) -> 26400 | I26: =+O26+(O26*$E$1) -> 10800 | K26: 32200 | L26: 14000 | M26: 18000 | N26: 22000 | O26: 9000
C27: SISTEMA REJILLA | E27: =+K27+(K27*$E$1) -> 38640 | F27: =+L27+(L27*$E$1) -> 16800 | G27: =+M27+(M27*$E$1) -> 21600 | H27: =+N27+(N27*$E$1) -> 26400 | I27: =+O27+(O27*$E$1) -> 10800 | K27: 32200 | L27: 14000 | M27: 18000 | N27: 22000 | O27: 9000
C28: SISTEMA SG CLARABOYA | E28: =+K28+(K28*$E$1) -> 38640 | F28: =+L28+(L28*$E$1) -> 16800 | G28: =+M28+(M28*$E$1) -> 21600 | H28: =+N28+(N28*$E$1) -> 26400 | I28: =+O28+(O28*$E$1) -> 10800 | K28: 32200 | L28: 14000 | M28: 18000 | N28: 22000 | O28: 9000
C29: CUERPO FIJO LINEA CLASSIC SISTEMA 3831 | E29: =+K29+(K29*$E$1) -> 38640 | F29: =+L29+(L29*$E$1) -> 16800 | G29: =+M29+(M29*$E$1) -> 21600 | H29: =+N29+(N29*$E$1) -> 26400 | I29: =+O29+(O29*$E$1) -> 10800 | K29: 32200 | L29: 14000 | M29: 18000 | N29: 22000 | O29: 9000
B30: DIVISIONES DE BAÑO | C30: DIVISIONES DE BAÑO CON ACCESORIOS EN ACERO INOXIDABLE | D30: Sistemas de lujo (cristal templado y accesorios), Corredizos y Embisagrados INOX | E30: =+K30+(K30*$E$1) -> 38640 | K30: 32200
B31: PUERTAS CORREDIZAS | C31: PUERTA CORREDIZA LINEA PREMIUM TIPO EUROPEO VENECIA NAPOLES | D31: Incluye: Lucetas, alfajias, tubulares, cristal, armada de marcos, recibidores y/o seguros. | E31: =+K31+(K31*$E$1) -> 38640 | F31: =+L31+(L31*$E$1) -> 55200 | G31: =+M31+(M31*$E$1) -> 69600 | H31: =+N31+(N31*$E$1) -> 84000 | I31: =+O31+(O31*$E$1) -> 31200 | K31: 32200 | L31: 46000 | M31: 58000 | N31: 70000 | O31: 26000
C32: VENTANA CORREDIZA LINEA PREMIUM TIPO EUROPEO VENECIA NAPOLES | E32: =+K32+(K32*$E$1) -> 38640 | F32: =+L32+(L32*$E$1) -> 55200 | G32: =+M32+(M32*$E$1) -> 69600 | H32: =+N32+(N32*$E$1) -> 84000 | I32: =+O32+(O32*$E$1) -> 31200 | K32: 32200 | L32: 46000 | M32: 58000 | N32: 70000 | O32: 26000
C33: PUERTA CORREDIZA LINEA PREMIUM TIPO EUROPEO VENECIA NAPOLES TIPO POKET | E33: =+K33+(K33*$E$1) -> 38640 | F33: =+L33+(L33*$E$1) -> 55200 | G33: =+M33+(M33*$E$1) -> 69600 | H33: =+N33+(N33*$E$1) -> 84000 | I33: =+O33+(O33*$E$1) -> 31200 | K33: 32200 | L33: 46000 | M33: 58000 | N33: 70000 | O33: 26000
C34: PUERTA CORREDIZA LINEA PREMIUM EUROPEO SISTEMA LSA 9052 | E34: =+K34+(K34*$E$1) -> 38640 | F34: =+L34+(L34*$E$1) -> 60000 | G34: =+M34+(M34*$E$1) -> 78000 | H34: =+N34+(N34*$E$1) -> 96000 | I34: =+O34+(O34*$E$1) -> 31200 | K34: 32200 | L34: 50000 | M34: 65000 | N34: 80000 | O34: 26000
C35: PUERTA CORREDIZA LINEA PREMIUM TIPO EUROPEO VENECIA MONACO | E35: =+K35+(K35*$E$1) -> 38640 | F35: =+L35+(L35*$E$1) -> 60000 | G35: =+M35+(M35*$E$1) -> 78000 | H35: =+N35+(N35*$E$1) -> 96000 | I35: =+O35+(O35*$E$1) -> 31200 | K35: 32200 | L35: 50000 | M35: 65000 | N35: 80000 | O35: 26000
B36: Puertas con marco de aluminio, no corredizas | C36: PUERTA BATIENTE LINEA PREMIUM TIPO EUROPEO VENECIA FERMO | D36: Sistemas colgante, plegable, embisagrada y pivotantes | E36: =+K36+(K36*$E$1) -> 38640 | F36: =+L36+(L36*$E$1) -> 72000 | G36: =+M36+(M36*$E$1) -> 114000 | H36: =+N36+(N36*$E$1) -> 150000 | I36: =+O36+(O36*$E$1) -> 10800 | K36: 32200 | L36: 60000 | M36: 95000 | N36: 125000 | O36: 9000
C37: PUERTA DOBLE BATIENTE LINEA PREMIUM TIPO EUROPEO VENECIA FERMO | E37: =+K37+(K37*$E$1) -> 38640 | F37: =+L37+(L37*$E$1) -> 72000 | G37: =+M37+(M37*$E$1) -> 114000 | H37: =+N37+(N37*$E$1) -> 150000 | I37: =+O37+(O37*$E$1) -> 10800 | K37: 32200 | L37: 60000 | M37: 95000 | N37: 125000 | O37: 9000
C38: PUERTA BATIENTE LINEA CLASSIC PRIMAVERA SIENA | E38: =+K38+(K38*$E$1) -> 38640 | F38: =+L38+(L38*$E$1) -> 60000 | G38: =+M38+(M38*$E$1) -> 105600 | H38: =+N38+(N38*$E$1) -> 117600 | I38: =+O38+(O38*$E$1) -> 10800 | K38: 32200 | L38: 50000 | M38: 88000 | N38: 98000 | O38: 9000
C39: PUERTA DOBLE BATIENTE LINEA CLASSIC SISTEMA SERIE SG 3890 | E39: =+K39+(K39*$E$1) -> 38640 | F39: =+L39+(L39*$E$1) -> 60000 | G39: =+M39+(M39*$E$1) -> 105600 | H39: =+N39+(N39*$E$1) -> 117600 | I39: =+O39+(O39*$E$1) -> 10800 | K39: 32200 | L39: 50000 | M39: 88000 | N39: 98000 | O39: 9000
C40: PUERTA BATIENTE LINEA CLASSIC SISTEMA SERIE SG 3890 | E40: =+K40+(K40*$E$1) -> 38640 | F40: =+L40+(L40*$E$1) -> 60000 | G40: =+M40+(M40*$E$1) -> 105600 | H40: =+N40+(N40*$E$1) -> 117600 | I40: =+O40+(O40*$E$1) -> 10800 | K40: 32200 | L40: 50000 | M40: 88000 | N40: 98000 | O40: 9000
...

Sheet COTIZACIÓN
BP2: BACKOFFICE OPERATIVO | BX2: VIATICOS | CF2: TRANSPORTES INTERMUNICIPALES
BP3: PARTICIPA | BQ3: VR SALARIO | BR3: VR PRESTACIONES | BS3: VR DIA | BT3: % CARGA | BU3: OCUPACIÓN DIAS | BV3: VR ACTIVIDAD | BX3: CIUDAD | BY3: VR DÍA ALIMENTACIÓN | BZ3: VR HAB, MOVILIZACION | CA3: VR DÍA | CB3: Nº DÍAS | CC3: VR TOTAL ALIMENTACIÓN | CD3: VR TOTAL HAB | CF3: CIUDAD | CG3: VR IDA Y VUELTA | CH3: Nº RETORNOS | CI3: VR TOTAL
N4: CODIGO | O4: FPP 002 | BP4: SISO | BQ4: =VLOOKUP(BP4,[1]Hoja1!$AE$5:$AH$93,2,FALSE) -> 1500000 | BR4: =BQ4*40% -> 600000 | BS4: =(BQ4+BR4)/20 -> 105000 | BU4: =IFERROR(ROUNDUP(BT14,0),"") -> 8 | BV4: =BS4*BU4*BT4 -> 0 | BX4: BGA | BY4: =VLOOKUP(BX4,[1]Hoja1!$AR$5:$AU$559,2,FALSE) -> 0 | BZ4: =VLOOKUP(BX4,[1]Hoja1!$AR$5:$AU$559,3,FALSE) -> 0 | CA4: =VLOOKUP(BX4,[1]Hoja1!$AR$5:$AU$559,4,FALSE) -> 0 | CC4: =BY4*CB4 -> 0 | CD4: =BZ4*CB4 -> 0 | CF4: BGA | CG4: =VLOOKUP(CF4,[1]Hoja1!$AW$5:$AX$1333,2,FALSE) -> 10000 | CI4: =CG4*CH4 -> 0 | CU4: RESUMEN
N5: VERSION | O5: V1 | BP5: MONTAJE | BQ5: 1700000 | BR5: =BQ5*40% -> 680000 | BS5: =(BQ5+BR5)/20 -> 119000 | BU5: =IFERROR(ROUNDUP(BT14,0),"") -> 8 | BV5: =BS5*BU5*BT5 -> 0 | BX5: BTA | BY5: =VLOOKUP(BX5,'BD GN'!BT:BW,2,FALSE) -> 45000 | BZ5: 65000 | CA5: =VLOOKUP(BX5,'BD GN'!BT:BW,4,FALSE) -> 110000 | CC5: =BY5*CB5 -> 0 | CD5: =BZ5*CB5 -> 0 | CF5: BTA | CG5: =VLOOKUP(CF5,[1]Hoja1!$AW$5:$AX$1333,2,FALSE) -> 180000 | CI5: =CG5*CH5 -> 0 | CU5: VR CONTRATO | CW5: 0 | CY5: VR EJECUTADO | DA5: =DB13 -> 0 | DC5: =IFERROR(DA5/$CW$9,"0%") -> 0%
N6: FECHA | O6: 44579 | BX6: ANTQ | BY6: =VLOOKUP(BX6,'BD GN'!BT:BW,2,FALSE) -> 45000 | BZ6: 65000 | CA6: =VLOOKUP(BX6,'BD GN'!BT:BW,4,FALSE) -> 110000 | CC6: =BY6*CB6 -> 0 | CD6: =BZ6*CB6 -> 0 | CF6: ANTQ | CG6: =VLOOKUP(CF6,'BD GN'!BY:BZ,2,FALSE) -> 280000 | CI6: =CG6*CH6 -> 0 | CU6: VR MODIFICACIONES | CW6: =(O343-CW5) -> 0 | CY6: VR PTE EJECUCION | DA6: =DD13 -> 0 | DC6: =IFERROR(DA6/$CW$9,"0%") -> 0%
A7: PROPUESTA ECONOMICA | N7: ELABORO | O7: ING ANDRES C. | Q7: CENTRO DE COSTOS UNT | AM7: CENTRO DE COSTOS TOTALES | BB7: CORTE 1 | BC7: V1 | BP7: M2 | BR7: VR | BX7: CALI | BY7: =VLOOKUP(BX7,'BD GN'!BT:BW,2,FALSE) -> 45000 | BZ7: 65000 | CA7: =VLOOKUP(BX7,'BD GN'!BT:BW,4,FALSE) -> 110000 | CC7: =BY7*CB7 -> 0 | CD7: =BZ7*CB7 -> 0 | CF7: CALI | CG7: =VLOOKUP(CF7,'BD GN'!BY:BZ,2,FALSE) -> 320000 | CI7: =CG7*CH7 -> 0 | CU7: VR ADICIONALES | CW7: =O1432 -> 0 | CY7: VR PAGADO | DA7: 0 | DC7: =IFERROR(DA7/$CW$9,"0%") -> 0%
N8: APROBO | O8: JUNTA D. | BP8: 0 | BQ8: 200 | BR8: 26000 | BX8: COSTA | BY8: =VLOOKUP(BX8,'BD GN'!BT:BW,2,FALSE) -> 45000 | BZ8: 65000 | CA8: =VLOOKUP(BX8,'BD GN'!BT:BW,4,FALSE) -> 110000 | CC8: =BY8*CB8 -> 0 | CD8: =BZ8*CB8 -> 0 | CF8: COSTA | CG8: =VLOOKUP(CF8,'BD GN'!BY:BZ,2,FALSE) -> 350000 | CI8: =CG8*CH8 -> 0 | CU8: VR ELIMINADOS | CW8: 0 | CY8: VR FACTURADO | DA8: 0 | DC8: =IFERROR(DA8/$CW$9,"0%") -> 0%
BB9: CORTE 2 | BC9: V2 | BF9: VIS | BG9: NO | BP9: 201 | BQ9: 550 | BR9: 13000 | CU9: VR FINAL | CW9: =CW5+CW6+CW7 -> 0 | CY9: VR PTE PAGO | DA9: =DA5-DA7 -> 0 | DC9: =IFERROR(DA9/$CW$9,"0%") -> 0%
A10: CLIENTE | E10: VERSIÓN | M10: ID PRESUPUESTO | BB10: CORTE 3 | BC10: V3 | BP10: 551 | BQ10: >1000 | BR10: 7000 | BU10: VR BACK ADM | BX10: NOTA. SI EL PROYECTO ES FUERA DE BGA SE DEBE CONTEMPLAR LOS VIATICOS DEL SUPERVISOR DE MONTAJE POR EL TIEMPO QUE DURE EL MISMO | CG10: Nº PERSONAS | CH10: VR VIATICOS | CI10: VR VIATICOS M2
A11: PROYECTO | E11: LINEA PRODUCCION | I11: ACORDADA | M11: FECHA ELABORACIÓN | O11: =+TODAY() -> 46203 | BB11: CORTE 4 | BC11: V4 | BF11: CINTA DE PROTECCIÓN | BG11: UNA CARA | BU11: =+IF(F339<=200,BR8,IF(AND(F339>200,F339<=550),BR9,BR10)) -> 26000 | CH11: =(SUM(CC4:CC8)+SUM(CD4:CD8)+SUM(CI4:CI8))*CG11 -> 0 | CI11: =IFERROR(CH11/F339,"")
A12: UBICACIÓN | E12: ELABORADO POR | I12: IVAN CANDELA | M12: VALIDEZ DE OFERTA | O12: 5 DIAS C | Q12: COSTO MATERIA PRIMA | T12: COSTO LOGÍSTICO | W12: M.O | AB12: COSTO ADM | AG12: COSTO VENTA | AM12: COSTO MATERIA PRIMA | AP12: COSTO LOGISTICO | AT12: M.O | AV12: COSTO ADM | AX12: PRECIO VENTA | BB12: CORTE 5 | BC12: V5 | BE12: INSUMOS VARIOS | BJ12: TRANSPORTE | BP12: TIEMPOS TEORICOS | CG12: MATERIALES Y EQUIPOS | CI12: VR MAT Y EQU M2 | CK12: PROCESO EJECUCION | CU12: CORTE 1 | CW12: CORTE 2 | CY12: CORTE 3 | DA12: LIQUIDADO | DC12: PTE X LIQUIDAR | DG12: RAD | DH12: CANTIDAD | DI12: SUBTOTAL | DJ12: TOTAL | DK12: ALU | DL12: ACC | DM12: VIDRIO | DN12: TRANSPORTE | DO12: VIATICOS | DP12: BACKOFFICE | DQ12: GAST VENTA | DR12: GAST FINANC | DS12: COSTOS IND | DT12: ENSAMBLE | DU12: INSTALACION | DV12: M2 INOX | DW12: M2 ALU | DX12: VR INOX | DY12: VR ALU
T13: 0.14 | U13: EMPQ | V13: TRANS | W13: LISTA PRECIOS | Y13: ='BD P&G'!E28+'BD P&G'!E30 -> 0.042320606 | Z13: ='BD P&G'!E29 -> 0.00584931 | AB13: 0.02 | AC13: IMPREV PYG | AD13: BACKOFFICE | AE13: ='BD P&G'!E7+'BD P&G'!E9+'BD P&G'!E10+'BD P&G'!E11+'BD P&G'!E16+'BD P&G'!E17+'BD P&G'!E18+'BD P&G'!E19+'BD P&G'!E20+'BD P&G'!E21+'BD P&G'!E22+'BD P&G'!E23+'BD P&G'!E32+'BD P&G'!E33+'BD P&G'!E34+'BD P&G'!E35+'BD P&G'!E36+'BD P&G'!E37+'BD P&G'!E38+'BD P&G'!E39 -> 0.064369776 | AF13: VIATICOS | AG13: 0.5 | AH13: BENEFICIO PYG | AI13: 0.02 | AJ13: ='BD P&G'!E44+'BD P&G'!E45 -> 0.00558 | AK13: VENTA SIN PYG | AL13: VENTA FINAL | AP13: 0.28 | AQ13: 0.01 | AR13: 0.02 | AS13: 0.055 | AV13: 0.01 | AW13: 0.03 | AX13: 0.6 | AY13: 0.03 | BB13: CORTE 6 | BC13: V6 | BE13: Nº MÓDULOS | BF13: VR SILICONA | BG13: VR PELÍCULA | BH13: VR EMBALAJE | BJ13: ESP. CRISTAL | BK13: PESO KG | BN13: VR TRANSP | BP13: FECHA INICIO | BQ13: FECHA FIN | BR13: DURACIÓN TOTAL | BS13: DURACIÓN PRODUCCIÓN | BT13: DURACIÓN MONTAJE | BU13: VR BACK | BV13: VR BACK/M2 | CH13: Extraido del formato equipos | CI13: =IFERROR(CG13/F339,"") | CK13: =SUM(CK14:CK2066) -> 0 | CL13: =SUM(CL14:CL2066) -> 0 | CM13: =SUM(CM14:CM2066) -> 0 | CN13: =SUM(CN14:CN2066) -> 0 | CO13: =SUM(CO14:CO2066) -> 0 | CP13: =SUM(CP14:CP2066) -> 0 | CQ13: =SUM(CQ14:CQ2066) -> 0 | CR13: =SUM(CR14:CR2066) -> 0 | ... CT13: =SUM(CT14:CT2066) -> 0 | CU13: =SUM(CU15:CU1996) -> 0 | CV13: =SUM(CV15:CV1996) -> 0 | CW13: =SUM(CW15:CW1996) -> 0 | CX13: =SUM(CX15:CX1996) -> 0 | CY13: =SUM(CY15:CY1996) -> 0 | CZ13: =SUM(CZ15:CZ1996) -> 0 | DA13: =SUM(DA15:DA1996) -> 0 | DB13: =SUM(DB15:DB1996) -> 0 | ... DD13: =SUM(DD15:DD1996) -> 0
A14: ÍTEM | B14: UBICACIÓN | C14: CONFIGURACIÓN | D14: DESCRIPCIÓN | J14: AN (MT) | K14: AL (MT) | L14: M2 | M14: CNT | N14: VR UNT | O14: VR TOTAL | Q14: ACCE | R14: ALUMINIO | S14: CRISTAL | T14: % DESP ALU | W14: ENSAMBLE | X14: INSTA | Y14: ENSAM PYG | Z14: INST PYG | AA14: TOTAL M.O PYG | AB14: IMPREV | AE14: PYG | AG14: BENEFICIO | AI14: COMISIÓN | AJ14: IMPUESTOS | AM14: ACCE | AN14: ALUMINIO | AO14: CRISTAL | AP14: % DESP ALU | AQ14: MAQ | AR14: EMPQ | AS14: TRANS | AT14: ENSAMBLE | AU14: INSTA | AV14: IMPREV | AW14: BACKOFFICE | AX14: UTILIDAD | AY14: COMISIÓN | AZ14: VENTA | BB14: CORTE 7 | BC14: V7 | BK14: ESTRUCTURA | BL14: CRISTAL | BM14: TOTAL | BR14: =(ROUNDUP(+F339*0.05,0)+7)+1.5 -> 8.5 | BS14: =ROUNDUP(BR14,0)*0.4 -> 3.6 | BT14: =(ROUNDUP(BR14,0)*0.6)+(2) -> 7.4 | BU14: =((SUM(BV4:BV5))) -> 0 | BV14: =IFERROR((BU14/F339)+BU11,"") | CK14: OR | CL14: MD | CM14: AD | CN14: EL | CO14: MD | CP14: PL | CQ14: PRO | CR14: DESP | CS14: MT | CT14: ENT | CU14: CNT | CV14: VR TOTAL | CW14: CNT | CX14: VR TOTAL | CY14: CNT | CZ14: VR TOTAL | DA14: CNT | DB14: VR TOTAL | DC14: CNT | DD14: VR TOTAL
C15: SISTEMA | L15: =J15*K15*M15 -> 0 | N15: =IFERROR(AL15,"") -> 1.0765547 | O15: =IFERROR(N15*M15,"") -> 0 | Q15: =Q16+BF15+($R$350*Q16) -> 0 | R15: =IFERROR(R16+($R$348*R16),"") -> 0 | S15: =+IF(R17="SI",((W19*'BD GN'!$AB$2)+S16)*1,COTIZACIÓN!S16*1)+(P16*S16) -> 0 | T15: =R15*T13 -> 0 | U15: =BH15+BG15 -> 0 | V15: =IFERROR(BN15,0) | W15: =IFERROR(IF(X17="SI",W18*J15*K15,IF(BE15=3,BE17,IF(BE15=4,BE18,IF(BE15=5,BE19,IF(BE15>5,BE19+(BE20*(BE15-5)),"")))))*0,"") | X15: =IFERROR(IF(X16="NO",(VLOOKUP(D15,'BD M.O'!C:E,3,FALSE))*W19,((VLOOKUP(D15,'BD M.O'!C:E,3,FALSE))+7500)*W19),"") | Y15: =IFERROR($Y$13*AK15,"") -> 0.042084457 | Z15: =IFERROR(($Z$13*AK15)+X15,"") | AA15: =IFERROR(Y15+Z15,"") | AB15: =IFERROR((SUM(Q15:X15)-T15+T17)*$AB$13,"") -> 0 | AC15: =IFERROR(((SUM(Q15:V15,IF(X20>AA15,AVERAGE(X20,AA15),AA15))-T15+T17))*$AB$13,"") -> 0 | AD15: =IFERROR((J15*K15*$BV$14),"") | AE15: =IFERROR($AE$13*AK15,"") -> 0.064010593 | AF15: =IFERROR(($CI$11+$CI$13)*W19,"") | AG15: =IFERROR((SUM(Q15:X15,AB15,AD15,AF15)-T15+T17)*$AG$13,"") -> 0 | AH15: =IFERROR((SUM(Q15:V15,(IF(X20>AA15,AVERAGE(X20,AA15),AA15)),AC15,AE15,AF15)-T15+T17)*$AG$13,"") -> 0.032005296 | AI15: =IFERROR(AL15*$AI$13,"") -> 0.021531093 | AJ15: =IFERROR($AJ$13*AL15,"") -> 0.006007175 | AK15: =IFERROR(SUM(Q15:X15,AB15,AD15,AG15,AF15)/(1-$AI$13)+(1-$AJ$13)-T15+T17,"") -> 0.99442 | AL15: =IFERROR(SUM(Q15:V15,AC15,(IF(AD15>AE15,AVERAGE(AD15,AE15),AE15)),AF15,,AH15,(IF(SUM(X20)>AA15,AVERAGE(AA15,X20),AA15)))/(1-$AJ$13)+(1-$AI$13)-T15+T17,"") -> 1.0765547 | AM15: =$M$15*Q15 -> 0 | AN15: =$M$15*R15 -> 0 | AO15: =$M$15*S15 -> 0 | AP15: =$M$15*T15 -> 0 | AQ15: =$M$15*#REF! -> #REF! | AR15: =$M$15*U15 -> 0 | AS15: =$M$15*V15 -> #VALUE! | AT15: =$M$15*W15 -> #VALUE! | AU15: =$M$15*X15 -> #VALUE! | AV15: =$M$15*AB15 -> 0 | AW15: =$M$15*AE15 -> 0 | AX15: =$M$15*AG15 -> 0 | AY15: =$M$15*AI15 -> 0 | AZ15: =$M$15*AK15 -> 0 | BB15: CORTE 8 | BC15: V8 | BF15: =IF(BH16="NO",((2*J15)+(2*K15))*'BD GN'!$AU$3,((3*J15)+(2*K15))*'BD GN'!$AU$3) -> 0 | BG15: ='BD GN'!$BB$3*J15*K15 -> 0 | BH15: =((J15*2*BE15)+(K15*2*BE15))*'BD GN'!$AN$4 -> 0 | BL15: =J15*K15*2.5*BJ15 -> 0 | BM15: =BK15+BL15 -> 0 | BN15: =IFERROR((VLOOKUP($C$12,'BD GN'!BD:BM,10,FALSE)*BM15)+$BR$338,"") | CV15: =IFERROR(N15*CU15,"") -> 0 | CX15: =IFERROR(P15*CW15,"") -> 0 | CZ15: =IFERROR(R15*CY15,"") -> 0 | DA15: =CU15+CW15+CY15 -> 0 | DB15: =IFERROR(CV15+CX15+CZ15,"") -> 0 | DC15: =M15-(CU15+CW15+CY15) -> 0 | DD15: =IFERROR(O15-(CV15+CX15+CZ15),"") -> 0 | DG15: 10001 | DH15: 1 | DI15: =IFERROR(IF(DG15>0,(((N15)/(1+10%+19%*5%)+((N15)/(1+10%+19%*5%))*10%)*DH15),0),0) -> 1.0673368 | DJ15: =IFERROR(IF(DG15>0,(N15*DH15),0),0) -> 1.0765547 | DK15: =IF(DG15>0,((R15+T15)*DH15),0) -> 0 | DL15: =IF(DG15>0,(Q15*DH15),0) -> 0 | DM15: =IF(DG15>0,(S15*DH15),0) -> 0 | DN15: =IF(DG15>0,(BN15*DH15),0) -> #VALUE! | DO15: =IF(DG15>0,(AF15*DH15),0) -> #VALUE! | DP15: =IF(DG15>0,((DI15)*('BD P&G'!$E$16+'BD P&G'!$E$17+'BD P&G'!$E$18+'BD P&G'!$E$19+'BD P&G'!$E$20+'BD P&G'!$E$21+'BD P&G'!$E$22+'BD P&G'!$E$23)*DH15),0) -> 0.029016015 | DQ15: =IFERROR(IF(DG15>0,((DI15*'BD P&G'!$E$7)+(DI15*'BD P&G'!$E$9)+AI15),0),0) -> 0.045823375 | DR15: =IFERROR(IF(DG15>0,((DI15*1%)),0),0) -> 0.010673368 | DS15: =IFERROR(IF(DG15>0,(((DI15*'BD P&G'!$E$32+DI15*'BD P&G'!$E$33+DI15*'BD P&G'!$E$35+DI15*'BD P&G'!$E$36+DI15*'BD P&G'!$E$37))),0),0) -> 0.011041197 | DT15: =IF(DG15>0,(Y15*DH15),0) -> 0.042084457 | DU15: =IF(DG15>0,(Z15*DH15),0) -> #VALUE! | DV15: =IF(DG15>0,(Y19*DH15),0) -> 0 | DW15: =IF(DG15>0,(Z19*DH15),0) -> 0 | DX15: =IF(DV15>0,DJ15,0) -> 0 | DY15: =IF(DW15>0,DJ15,0) -> 0
C16: CRISTAL | T16: =IFERROR(T15/$R$353,"") -> 0 | W16: ANGEO | X16: NO | BB16: CORTE 9 | BC16: V9 | BE16: ALFAJÍA | BF16: NO | BG16: LUCETA | BH16: NO | BP16: TIEMPOS PYG
C17: ACABADO ALUMINIO | Q17: SANDBLASTING | R17: NO | T17: =IFERROR(($R$353-8000)*T16,"") -> 0 | W17: FACHADA | X17: NO | BB17: CORTE 10 | BC17: V10 | BE17: =IFERROR(VLOOKUP(D15,'BD M.O'!C:H,4,FALSE),"") | BF17: 2HOJAS | BP17: FECHA INICIO | BQ17: FECHA FIN | BR17: DURACIÓN TOTAL | BS17: DURACIÓN PRODUCCIÓN | BT17: DURACIÓN MONTAJE
C18: PELÍCULA PROTECCIÓN | D18: PERFILES | F18: X | G18: CRISTAL | I18: =+IF($BG$9="SI","","X") -> X | R18: VIDRIO M2 | S18: =IF(S16="","",S16/(J15*K15)) | W18: =IFERROR(IF(X17="SI",VLOOKUP(D15,'BD M.O'!C:F,4,FALSE),""),"") | X18: FACHADA | Y18: M2 INOX | Z18: M2 ALU | BC18: V11 | BE18: =IFERROR(VLOOKUP(COTIZACIÓN!D15,'BD M.O'!C:I,5,FALSE),"") | BF18: 3HOJAS | BR18: =IFERROR((SUM(Y340:Z340)),"") -> 0 | BS18: =Y340 -> 0 | BT18: =Z340 -> 0 | DI18: =IFERROR(IF(DG18>0,(((N15)/(1+10%+19%*5%)+((N15)/(1+10%+19%*5%))*10%)*DH18),0),0) -> 0 | DJ18: =IFERROR(IF(DG18>0,(N15*DH18),0),0) -> 0 | DK18: =IF(DG18>0,((R15+T15)*DH18),0) -> 0 | DL18: =IF(DG18>0,(Q15*DH18),0) -> 0 | DM18: =IF(DG18>0,(S15*DH18),0) -> 0 | DN18: =IF(DG18>0,(BN15*DH18),0) -> 0 | DO18: =IF(DG18>0,(AF15*DH18),0) -> 0 | DP18: =IF(DG18>0,((DI18)*('BD P&G'!$E$16+'BD P&G'!$E$17+'BD P&G'!$E$18+'BD P&G'!$E$19+'BD P&G'!$E$20+'BD P&G'!$E$21+'BD P&G'!$E$22+'BD P&G'!$E$23)*DH18),0) -> 0 | DQ18: =IFERROR(IF(DG18>0,((DI18*'BD P&G'!$E$7)+(DI18*'BD P&G'!$E$9)+AI15),0),0) -> 0 | DR18: =IFERROR(IF(DG18>0,((DI18*1%)),0),0) -> 0 | DS18: =IFERROR(IF(DG18>0,(((DI18*'BD P&G'!$E$32+DI18*'BD P&G'!$E$33+DI18*'BD P&G'!$E$35+DI18*'BD P&G'!$E$36+DI18*'BD P&G'!$E$37))),0),0) -> 0 | DT18: =IF(DG18>0,(Y15*DH18),0) -> 0 | DU18: =IF(DG18>0,(Z15*DH18),0) -> 0 | DV18: =IF(DG18>0,(Y19*DH18),0) -> 0 | DW18: =IF(DG18>0,(Z19*DH18),0) -> 0 | DX18: =IF(DV18>0,DJ18,0) -> 0 | DY18: =IF(DW18>0,DJ18,0) -> 0
C19: CERRADURA | D19: =IFERROR(VLOOKUP(D15,'BD GN'!C:E,3,),"") | R19: SISTEMA M2 | S19: =IFERROR(IF(N15="","",N15/W19),"") | W19: =+IF(J15*K15>=1,J15*K15,IF(AND(J15*K15>0,J15*K15<1),1,"")) | X19: AREA | Y19: =IFERROR(IF(D15='BD GN'!$C$25,COTIZACIÓN!W19,IF(D15='BD GN'!$C$26,COTIZACIÓN!W19,IF(D15='BD GN'!$C$27,COTIZACIÓN!W19,IF(COTIZACIÓN!D15='BD GN'!$C$28,COTIZACIÓN!W19,IF(COTIZACIÓN!D15='BD GN'!$C$29,COTIZACIÓN!W19,IF(COTIZACIÓN!D15='BD GN'!$C$35,COTIZACIÓN!W19,IF(COTIZACIÓN!D15='BD GN'!$C$36,COTIZACIÓN!W19,IF(COTIZACIÓN!D15='BD GN'!$C$37,COTIZACIÓN!W19,IF(COTIZACIÓN!D15='BD GN'!$C$38,COTIZACIÓN!W19,IF(COTIZACIÓN!D15='BD GN'!$C$39,COTIZACIÓN!W19,IF(COTIZACIÓN!D15='BD GN'!$C$40,COTIZACIÓN!W19,IF(COTIZACIÓN!D15='BD GN'!$C$41,COTIZACIÓN!W19,IF(COTIZACIÓN!D15='BD GN'!$C$42,COTIZACIÓN!W19,IF(COTIZACIÓN!D15='BD GN'!$C$49,COTIZACIÓN!W19,IF(COTIZACIÓN!D15='BD GN'!$C$50,COTIZACIÓN!W19,IF(COTIZACIÓN!D15='BD GN'!$C$51,COTIZACIÓN!W19,IF(COTIZACIÓN!D15='BD GN'!$C$67,COTIZACIÓN!W19,0))))))))))))))))),0) -> 0 | Z19: =IFERROR(W19-Y19,0) -> 0 | BC19: V12 | BE19: =IFERROR(VLOOKUP(D15,'BD M.O'!C:I,6,FALSE),"") | BF19: 4HOJAS
C20: OBSERVACIONES | D20: N.A | R20: VR REF SIS M2 | S20: =IFERROR(IF($C$12='BD GN'!$CC$1,VLOOKUP(COTIZACIÓN!D15,'BD GN'!CB:CG,2,FALSE),IF(COTIZACIÓN!$C$12='BD GN'!$CD$1,VLOOKUP(COTIZACIÓN!D15,'BD GN'!CB:CG,3,FALSE),IF($C$12='BD GN'!$CE$1,VLOOKUP(COTIZACIÓN!D15,'BD GN'!CB:CG,4,FALSE),IF(COTIZACIÓN!$C$12='BD GN'!$CF$1,VLOOKUP(COTIZACIÓN!D15,'BD GN'!CB:CG,5,FALSE),IF(COTIZACIÓN!$C$12='BD GN'!$CG$1,VLOOKUP(COTIZACIÓN!D15,'BD GN'!CB:CG,6,FALSE),""))))),"-") | W20: TOTAL M.O | X20: =IFERROR(SUM(W15:X15),"") -> 0 | Y20: TOTAL M.O PYG | Z20: =IFERROR(Y15+Z15,"") | BC20: V13 | BE20: =IFERROR(VLOOKUP(D15,'BD M.O'!C:I,7,FALSE),"") | BF20: HOJA ADIC
